Workbook
Name AcoesRecursosHidricos_IDs: "MAPEAMENTO_ACOES!$A$5#"
Name Actions: [2]Lists!$L$2:$L$61
Name Diroconnector_: #REF!
Name ImpactActionIDs: 'Bank of actions'!$A$3:$A$55
Name ImpactScaledActionIDs: Table24[ActionID]
Name ImpactScaledActionIDs: [1]!Table24[ActionID]
Name ImpactScaledActionIDs: Table24[ActionID]
Name ImpactScaledActionIDs: Table24[ActionID]
Name ImpactScaledActionIDs: Table24[ActionID]
Name ImpactScaledActionIDs: Table24[ActionID]
Name ImpactScaledActionIDs: Table24[ActionID]
Name ImpactScaledActionIDs: Table24[ActionID]
Name Palm_indonesia: #REF!
Name Palm_malaysia: #REF!
Name WR_AccessStatus: tbl_Lists_AccessStatus[AccessStatus]
Name WR_AccessStatus: tbl_Lists_AccessStatus[AccessStatus]
Name WR_AccessStatus: tbl_Lists_AccessStatus[AccessStatus]
Name WR_AccessStatus: tbl_Lists_AccessStatus[AccessStatus]
Name WR_AccessStatus: tbl_Lists_AccessStatus[AccessStatus]
Name WR_AccessStatus: tbl_Lists_AccessStatus[AccessStatus]
Name WR_EffectivenessLevel: tbl_Lists_EffectivenessLevel[EffectivenessLevel]
Name WR_EffectivenessLevel: tbl_Lists_EffectivenessLevel[EffectivenessLevel]
Name WR_EffectivenessLevel: tbl_Lists_EffectivenessLevel[EffectivenessLevel]
Name WR_EffectivenessLevel: tbl_Lists_EffectivenessLevel[EffectivenessLevel]
Name WR_EffectivenessLevel: tbl_Lists_EffectivenessLevel[EffectivenessLevel]
Name WR_EffectivenessLevel: tbl_Lists_EffectivenessLevel[EffectivenessLevel]
Name WR_EvidenceStrength: tbl_Lists_EvidenceStrength[EvidenceStrength]
Name WR_EvidenceStrength: tbl_Lists_EvidenceStrength[EvidenceStrength]
Name WR_EvidenceStrength: tbl_Lists_EvidenceStrength[EvidenceStrength]
Name WR_EvidenceStrength: tbl_Lists_EvidenceStrength[EvidenceStrength]
Name WR_EvidenceStrength: tbl_Lists_EvidenceStrength[EvidenceStrength]
Name WR_EvidenceStrength: tbl_Lists_EvidenceStrength[EvidenceStrength]
Name WR_ExposureComponents: _xlfn.ANCHORARRAY(Lists!$E$22)
Name WR_ExposureSectors: _xlfn.ANCHORARRAY(Lists!$D$22)
Name WR_HumanValidated: tbl_Lists_HumanValidated[HumanValidated]
Name WR_HumanValidated: tbl_Lists_HumanValidated[HumanValidated]
Name WR_HumanValidated: tbl_Lists_HumanValidated[HumanValidated]
Name WR_HumanValidated: tbl_Lists_HumanValidated[HumanValidated]
Name WR_HumanValidated: tbl_Lists_HumanValidated[HumanValidated]
Name WR_HumanValidated: tbl_Lists_HumanValidated[HumanValidated]
Name WR_RelevantComponent: tbl_Lists_RelevantComponent[RelevantComponent]
Name WR_RelevantComponent: tbl_Lists_RelevantComponent[RelevantComponent]
Name WR_RelevantComponent: tbl_Lists_RelevantComponent[RelevantComponent]
Name WR_RelevantComponent: tbl_Lists_RelevantComponent[RelevantComponent]
Name WR_RelevantComponent: tbl_Lists_RelevantComponent[RelevantComponent]
Name WR_RelevantComponent: tbl_Lists_RelevantComponent[RelevantComponent]
Name WR_ReviewStatus: tbl_Lists_ReviewStatus[ReviewStatus]
Name WR_ReviewStatus: tbl_Lists_ReviewStatus[ReviewStatus]
Name WR_ReviewStatus: tbl_Lists_ReviewStatus[ReviewStatus]
Name WR_ReviewStatus: tbl_Lists_ReviewStatus[ReviewStatus]
Name WR_ReviewStatus: tbl_Lists_ReviewStatus[ReviewStatus]
Name WR_ReviewStatus: tbl_Lists_ReviewStatus[ReviewStatus]
Name WR_SourceScope: tbl_Lists_SourceScope[SourceScope]
Name WR_SourceScope: tbl_Lists_SourceScope[SourceScope]
Name WR_SourceScope: tbl_Lists_SourceScope[SourceScope]
Name WR_SourceScope: tbl_Lists_SourceScope[SourceScope]
Name WR_SourceScope: tbl_Lists_SourceScope[SourceScope]
Name WR_SourceScope: tbl_Lists_SourceScope[SourceScope]
Name WR_VulnerabilityComponents: _xlfn.ANCHORARRAY(Lists!$B$22)
Name WR_VulnerabilitySectors: _xlfn.ANCHORARRAY(Lists!$A$22)

Sheet Home
B2: Sector-action linkage assessment
B3: Methodological workbook for sector eligibility and effectiveness assessment using AI-supported evidence review
B6: Date | C6: 26/08/2026
B7: Author | C7: I Care Brasil
B8: Version | C8: Working draft
B10: What is this workbook for?
B11: This workbook establishes direct links between adaptation actions and sectors. Eligibility is assessed first; effectiveness is assessed only for eligible actions. The resulting effectiveness values are intended to become inputs to the Impact Assessment.
B12: How is the process structured?
B13: CURRENT PROCESS 1. Step 0 — Indicator Framework Construction: build the approved sector framework by grouping Level 6 Vulnerability and Exposure indicators under their respective Level 3 components. 2. Step 1 — Source Identification: identify and validate 5 Brazilian and 5 international PDF sources. 3. Step 2 — Combined Assessment: the same prompt assesses sector eligibility and effectiveness together using the available evidence.
B16: Target process
B17: TARGET PROCESS 1. Step 0 — Indicator Framework Construction: retain the same approved sector framework. 2. Step 1 — Source Identification: retain the same validated PDF portfolio. 3. Step 2A — Eligibility Assessment: run a dedicated prompt that determines only whether each action has a direct relationship with approved Vulnerability or Exposure indicators. No effectiveness level is assigned. 4. Human review: validate the eligibility results before proceeding. 5. Step 2B — Effectiveness Assessment: run a separate prompt, limited to actions already classified as Eligible, and progressively append evidence from reviewed PDFs.
B20: Why separate eligibility and effectiveness?
B21: Eligibility asks: “Does the action belong to this sector through a direct indicator relationship?” Effectiveness asks: “How strong is the evidence that this action reduces the approved indicator?” Keeping them in separate prompts prevents the effectiveness evidence from influencing the prior eligibility decision.
B24: Important note on AI use
B25: AI is used as a decision-support tool. Outputs depend on source quality, PDF coverage, prompt design and interpretation of evidence. Extensive validation rules reduce risks, but limitations and uncertainty remain. Human review is recommended for critical methodological decisions. Results should be interpreted as evidence-supported expert judgement, not fully automated conclusions.
B29: How to use the workbook
B30: 1. The current sector worksheets still use a combined Step 2 prompt. 2. Use Water Resources x actions as the completed current-process example. 3. For the target process, run a standalone Step 2A prompt, validate eligibility, then run a separate Step 2B prompt for Eligible actions only. 4. Review consolidated results in Summary Matrix and use effectiveness values in the Impact Assessment.
B34: Key worksheets
B35: Summary Matrix | E35: Consolidated links and effectiveness values
B36: Water Resources x actions | E36: Completed pilot and reference workflow
B37: Other sector worksheets | E37: Run Step 2A and Step 2B independently for each sector
B38: Score assessments | E38: Downstream Impact Assessment tests

Sheet Summary Matrix
B2: SUMMARY MATRIX - AUTOMATIC VALUES FROM SECTOR BLOCKS
B3: ActionID | C3: ActionName | D3: Water Resources | E3: Food Security | F3: Energy Security | G3: Health | H3: Geohydrological Disasters | I3: Biodiversity
B4: c40_0046 | C4: Strengthen coastal protection infrastructure | D4: =IFERROR(_xlfn.LET(_xlpm.v,_xlfn.XLOOKUP(tbl_Summary_Linkage[[#This Row],[ActionID]],tbl_WR_Assessment[ActionID],tbl_WR_Assessment[Effectiveness on Vulnerability],""),_xlpm.e,_xlfn.XLOOKUP(tbl_Summary_Linkage[[#This Row],[ActionID]],tbl_WR_Assessment[ActionID],tbl_WR_Assessment[Effectiveness on Exposure],""),IF(OR(_xlpm.v="High effectiveness",_xlpm.v="Medium effectiveness",_xlpm.v="Low effectiveness",_xlpm.e="High effectiveness",_xlpm.e="Medium effectiveness",_xlpm.e="Low effectiveness"),"Yes","")),"") | E4: =IFERROR(_xlfn.LET(_xlpm.v,_xlfn.XLOOKUP(tbl_Summary_Linkage[[#This Row],[ActionID]],tbl_FS_Assessment[ActionID],tbl_FS_Assessment[Effectiveness on Vulnerability],""),_xlpm.e,_xlfn.XLOOKUP(tbl_Summary_Linkage[[#This Row],[ActionID]],tbl_FS_Assessment[ActionID],tbl_FS_Assessment[Effectiveness on Exposure],""),IF(OR(_xlpm.v="High effectiveness",_xlpm.v="Medium effectiveness",_xlpm.v="Low effectiveness",_xlpm.e="High effectiveness",_xlpm.e="Medium effectiveness",_xlpm.e="Low effectiveness"),"Yes","")),"") | F4: =IFERROR(_xlfn.LET(_xlpm.v,_xlfn.XLOOKUP(tbl_Summary_Linkage[[#This Row],[ActionID]],tbl_ES_Assessment[ActionID],tbl_ES_Assessment[Effectiveness on Vulnerability],""),_xlpm.e,_xlfn.XLOOKUP(tbl_Summary_Linkage[[#This Row],[ActionID]],tbl_ES_Assessment[ActionID],tbl_ES_Assessment[Effectiveness on Exposure],""),IF(OR(_xlpm.v="High effectiveness",_xlpm.v="Medium effectiveness",_xlpm.v="Low effectiveness",_xlpm.e="High effectiveness",_xlpm.e="Medium effectiveness",_xlpm.e="Low effectiveness"),"Yes","")),"") | G4: =IFERROR(_xlfn.LET(_xlpm.v,_xlfn.XLOOKUP(tbl_Summary_Linkage[[#This Row],[ActionID]],tbl_H_Assessment[ActionID],tbl_H_Assessment[Effectiveness on Vulnerability],""),_xlpm.e,_xlfn.XLOOKUP(tbl_Summary_Linkage[[#This Row],[ActionID]],tbl_H_Assessment[ActionID],tbl_H_Assessment[Effectiveness on Exposure],""),IF(OR(_xlpm.v="High effectiveness",_xlpm.v="Medium effectiveness",_xlpm.v="Low effectiveness",_xlpm.e="High effectiveness",_xlpm.e="Medium effectiveness",_xlpm.e="Low effectiveness"),"Yes","")),"") | H4: =IFERROR(_xlfn.LET(_xlpm.v,_xlfn.XLOOKUP(tbl_Summary_Linkage[[#This Row],[ActionID]],tbl_GS_Assessment[ActionID],tbl_GS_Assessment[Effectiveness on Vulnerability],""),_xlpm.e,_xlfn.XLOOKUP(tbl_Summary_Linkage[[#This Row],[ActionID]],tbl_GS_Assessment[ActionID],tbl_GS_Assessment[Effectiveness on Exposure],""),IF(OR(_xlpm.v="High effectiveness",_xlpm.v="Medium effectiveness",_xlpm.v="Low effectiveness",_xlpm.e="High effectiveness",_xlpm.e="Medium effectiveness",_xlpm.e="Low effectiveness"),"Yes","")),"") | I4: =IFERROR(_xlfn.LET(_xlpm.v,_xlfn.XLOOKUP(tbl_Summary_Linkage[[#This Row],[ActionID]],tbl_B_Assessment[ActionID],tbl_B_Assessment[Effectiveness on Vulnerability],""),_xlpm.e,_xlfn.XLOOKUP(tbl_Summary_Linkage[[#This Row],[ActionID]],tbl_B_Assessment[ActionID],tbl_B_Assessment[Effectiveness on Exposure],""),IF(OR(_xlpm.v="High effectiveness",_xlpm.v="Medium effectiveness",_xlpm.v="Low effectiveness",_xlpm.e="High effectiveness",_xlpm.e="Medium effectiveness",_xlpm.e="Low effectiveness"),"Yes","")),"")
B5: c40_0048 | C5: Upgrade urban drainage systems | D5: =IFERROR(_xlfn.LET(_xlpm.v,_xlfn.XLOOKUP(tbl_Summary_Linkage[[#This Row],[ActionID]],tbl_WR_Assessment[ActionID],tbl_WR_Assessment[Effectiveness on Vulnerability],""),_xlpm.e,_xlfn.XLOOKUP(tbl_Summary_Linkage[[#This Row],[ActionID]],tbl_WR_Assessment[ActionID],tbl_WR_Assessment[Effectiveness on Exposure],""),IF(OR(_xlpm.v="High effectiveness",_xlpm.v="Medium effectiveness",_xlpm.v="Low effectiveness",_xlpm.e="High effectiveness",_xlpm.e="Medium effectiveness",_xlpm.e="Low effectiveness"),"Yes","")),"") -> Yes | E5: =IFERROR(_xlfn.LET(_xlpm.v,_xlfn.XLOOKUP(tbl_Summary_Linkage[[#This Row],[ActionID]],tbl_FS_Assessment[ActionID],tbl_FS_Assessment[Effectiveness on Vulnerability],""),_xlpm.e,_xlfn.XLOOKUP(tbl_Summary_Linkage[[#This Row],[ActionID]],tbl_FS_Assessment[ActionID],tbl_FS_Assessment[Effectiveness on Exposure],""),IF(OR(_xlpm.v="High effectiveness",_xlpm.v="Medium effectiveness",_xlpm.v="Low effectiveness",_xlpm.e="High effectiveness",_xlpm.e="Medium effectiveness",_xlpm.e="Low effectiveness"),"Yes","")),"") | F5: =IFERROR(_xlfn.LET(_xlpm.v,_xlfn.XLOOKUP(tbl_Summary_Linkage[[#This Row],[ActionID]],tbl_ES_Assessment[ActionID],tbl_ES_Assessment[Effectiveness on Vulnerability],""),_xlpm.e,_xlfn.XLOOKUP(tbl_Summary_Linkage[[#This Row],[ActionID]],tbl_ES_Assessment[ActionID],tbl_ES_Assessment[Effectiveness on Exposure],""),IF(OR(_xlpm.v="High effectiveness",_xlpm.v="Medium effectiveness",_xlpm.v="Low effectiveness",_xlpm.e="High effectiveness",_xlpm.e="Medium effectiveness",_xlpm.e="Low effectiveness"),"Yes","")),"") | G5: =IFERROR(_xlfn.LET(_xlpm.v,_xlfn.XLOOKUP(tbl_Summary_Linkage[[#This Row],[ActionID]],tbl_H_Assessment[ActionID],tbl_H_Assessment[Effectiveness on Vulnerability],""),_xlpm.e,_xlfn.XLOOKUP(tbl_Summary_Linkage[[#This Row],[ActionID]],tbl_H_Assessment[ActionID],tbl_H_Assessment[Effectiveness on Exposure],""),IF(OR(_xlpm.v="High effectiveness",_xlpm.v="Medium effectiveness",_xlpm.v="Low effectiveness",_xlpm.e="High effectiveness",_xlpm.e="Medium effectiveness",_xlpm.e="Low effectiveness"),"Yes","")),"") | H5: =IFERROR(_xlfn.LET(_xlpm.v,_xlfn.XLOOKUP(tbl_Summary_Linkage[[#This Row],[ActionID]],tbl_GS_Assessment[ActionID],tbl_GS_Assessment[Effectiveness on Vulnerability],""),_xlpm.e,_xlfn.XLOOKUP(tbl_Summary_Linkage[[#This Row],[ActionID]],tbl_GS_Assessment[ActionID],tbl_GS_Assessment[Effectiveness on Exposure],""),IF(OR(_xlpm.v="High effectiveness",_xlpm.v="Medium effectiveness",_xlpm.v="Low effectiveness",_xlpm.e="High effectiveness",_xlpm.e="Medium effectiveness",_xlpm.e="Low effectiveness"),"Yes","")),"") | I5: =IFERROR(_xlfn.LET(_xlpm.v,_xlfn.XLOOKUP(tbl_Summary_Linkage[[#This Row],[ActionID]],tbl_B_Assessment[ActionID],tbl_B_Assessment[Effectiveness on Vulnerability],""),_xlpm.e,_xlfn.XLOOKUP(tbl_Summary_Linkage[[#This Row],[ActionID]],tbl_B_Assessment[ActionID],tbl_B_Assessment[Effectiveness on Exposure],""),IF(OR(_xlpm.v="High effectiveness",_xlpm.v="Medium effectiveness",_xlpm.v="Low effectiveness",_xlpm.e="High effectiveness",_xlpm.e="Medium effectiveness",_xlpm.e="Low effectiveness"),"Yes","")),"")
B6: c40_0049 | C6: Build and maintain shelters for critical climate hazards | D6: =IFERROR(_xlfn.LET(_xlpm.v,_xlfn.XLOOKUP(tbl_Summary_Linkage[[#This Row],[ActionID]],tbl_WR_Assessment[ActionID],tbl_WR_Assessment[Effectiveness on Vulnerability],""),_xlpm.e,_xlfn.XLOOKUP(tbl_Summary_Linkage[[#This Row],[ActionID]],tbl_WR_Assessment[ActionID],tbl_WR_Assessment[Effectiveness on Exposure],""),IF(OR(_xlpm.v="High effectiveness",_xlpm.v="Medium effectiveness",_xlpm.v="Low effectiveness",_xlpm.e="High effectiveness",_xlpm.e="Medium effectiveness",_xlpm.e="Low effectiveness"),"Yes","")),"") | E6: =IFERROR(_xlfn.LET(_xlpm.v,_xlfn.XLOOKUP(tbl_Summary_Linkage[[#This Row],[ActionID]],tbl_FS_Assessment[ActionID],tbl_FS_Assessment[Effectiveness on Vulnerability],""),_xlpm.e,_xlfn.XLOOKUP(tbl_Summary_Linkage[[#This Row],[ActionID]],tbl_FS_Assessment[ActionID],tbl_FS_Assessment[Effectiveness on Exposure],""),IF(OR(_xlpm.v="High effectiveness",_xlpm.v="Medium effectiveness",_xlpm.v="Low effectiveness",_xlpm.e="High effectiveness",_xlpm.e="Medium effectiveness",_xlpm.e="Low effectiveness"),"Yes","")),"") | F6: =IFERROR(_xlfn.LET(_xlpm.v,_xlfn.XLOOKUP(tbl_Summary_Linkage[[#This Row],[ActionID]],tbl_ES_Assessment[ActionID],tbl_ES_Assessment[Effectiveness on Vulnerability],""),_xlpm.e,_xlfn.XLOOKUP(tbl_Summary_Linkage[[#This Row],[ActionID]],tbl_ES_Assessment[ActionID],tbl_ES_Assessment[Effectiveness on Exposure],""),IF(OR(_xlpm.v="High effectiveness",_xlpm.v="Medium effectiveness",_xlpm.v="Low effectiveness",_xlpm.e="High effectiveness",_xlpm.e="Medium effectiveness",_xlpm.e="Low effectiveness"),"Yes","")),"") | G6: =IFERROR(_xlfn.LET(_xlpm.v,_xlfn.XLOOKUP(tbl_Summary_Linkage[[#This Row],[ActionID]],tbl_H_Assessment[ActionID],tbl_H_Assessment[Effectiveness on Vulnerability],""),_xlpm.e,_xlfn.XLOOKUP(tbl_Summary_Linkage[[#This Row],[ActionID]],tbl_H_Assessment[ActionID],tbl_H_Assessment[Effectiveness on Exposure],""),IF(OR(_xlpm.v="High effectiveness",_xlpm.v="Medium effectiveness",_xlpm.v="Low effectiveness",_xlpm.e="High effectiveness",_xlpm.e="Medium effectiveness",_xlpm.e="Low effectiveness"),"Yes","")),"") | H6: =IFERROR(_xlfn.LET(_xlpm.v,_xlfn.XLOOKUP(tbl_Summary_Linkage[[#This Row],[ActionID]],tbl_GS_Assessment[ActionID],tbl_GS_Assessment[Effectiveness on Vulnerability],""),_xlpm.e,_xlfn.XLOOKUP(tbl_Summary_Linkage[[#This Row],[ActionID]],tbl_GS_Assessment[ActionID],tbl_GS_Assessment[Effectiveness on Exposure],""),IF(OR(_xlpm.v="High effectiveness",_xlpm.v="Medium effectiveness",_xlpm.v="Low effectiveness",_xlpm.e="High effectiveness",_xlpm.e="Medium effectiveness",_xlpm.e="Low effectiveness"),"Yes","")),"") | I6: =IFERROR(_xlfn.LET(_xlpm.v,_xlfn.XLOOKUP(tbl_Summary_Linkage[[#This Row],[ActionID]],tbl_B_Assessment[ActionID],tbl_B_Assessment[Effectiveness on Vulnerability],""),_xlpm.e,_xlfn.XLOOKUP(tbl_Summary_Linkage[[#This Row],[ActionID]],tbl_B_Assessment[ActionID],tbl_B_Assessment[Effectiveness on Exposure],""),IF(OR(_xlpm.v="High effectiveness",_xlpm.v="Medium effectiveness",_xlpm.v="Low effectiveness",_xlpm.e="High effectiveness",_xlpm.e="Medium effectiveness",_xlpm.e="Low effectiveness"),"Yes","")),"")
B7: c40_0051 | C7: Provide public shading in heat hotspots | D7: =IFERROR(_xlfn.LET(_xlpm.v,_xlfn.XLOOKUP(tbl_Summary_Linkage[[#This Row],[ActionID]],tbl_WR_Assessment[ActionID],tbl_WR_Assessment[Effectiveness on Vulnerability],""),_xlpm.e,_xlfn.XLOOKUP(tbl_Summary_Linkage[[#This Row],[ActionID]],tbl_WR_Assessment[ActionID],tbl_WR_Assessment[Effectiveness on Exposure],""),IF(OR(_xlpm.v="High effectiveness",_xlpm.v="Medium effectiveness",_xlpm.v="Low effectiveness",_xlpm.e="High effectiveness",_xlpm.e="Medium effectiveness",_xlpm.e="Low effectiveness"),"Yes","")),"") | E7: =IFERROR(_xlfn.LET(_xlpm.v,_xlfn.XLOOKUP(tbl_Summary_Linkage[[#This Row],[ActionID]],tbl_FS_Assessment[ActionID],tbl_FS_Assessment[Effectiveness on Vulnerability],""),_xlpm.e,_xlfn.XLOOKUP(tbl_Summary_Linkage[[#This Row],[ActionID]],tbl_FS_Assessment[ActionID],tbl_FS_Assessment[Effectiveness on Exposure],""),IF(OR(_xlpm.v="High effectiveness",_xlpm.v="Medium effectiveness",_xlpm.v="Low effectiveness",_xlpm.e="High effectiveness",_xlpm.e="Medium effectiveness",_xlpm.e="Low effectiveness"),"Yes","")),"") | F7: =IFERROR(_xlfn.LET(_xlpm.v,_xlfn.XLOOKUP(tbl_Summary_Linkage[[#This Row],[ActionID]],tbl_ES_Assessment[ActionID],tbl_ES_Assessment[Effectiveness on Vulnerability],""),_xlpm.e,_xlfn.XLOOKUP(tbl_Summary_Linkage[[#This Row],[ActionID]],tbl_ES_Assessment[ActionID],tbl_ES_Assessment[Effectiveness on Exposure],""),IF(OR(_xlpm.v="High effectiveness",_xlpm.v="Medium effectiveness",_xlpm.v="Low effectiveness",_xlpm.e="High effectiveness",_xlpm.e="Medium effectiveness",_xlpm.e="Low effectiveness"),"Yes","")),"") | G7: =IFERROR(_xlfn.LET(_xlpm.v,_xlfn.XLOOKUP(tbl_Summary_Linkage[[#This Row],[ActionID]],tbl_H_Assessment[ActionID],tbl_H_Assessment[Effectiveness on Vulnerability],""),_xlpm.e,_xlfn.XLOOKUP(tbl_Summary_Linkage[[#This Row],[ActionID]],tbl_H_Assessment[ActionID],tbl_H_Assessment[Effectiveness on Exposure],""),IF(OR(_xlpm.v="High effectiveness",_xlpm.v="Medium effectiveness",_xlpm.v="Low effectiveness",_xlpm.e="High effectiveness",_xlpm.e="Medium effectiveness",_xlpm.e="Low effectiveness"),"Yes","")),"") | H7: =IFERROR(_xlfn.LET(_xlpm.v,_xlfn.XLOOKUP(tbl_Summary_Linkage[[#This Row],[ActionID]],tbl_GS_Assessment[ActionID],tbl_GS_Assessment[Effectiveness on Vulnerability],""),_xlpm.e,_xlfn.XLOOKUP(tbl_Summary_Linkage[[#This Row],[ActionID]],tbl_GS_Assessment[ActionID],tbl_GS_Assessment[Effectiveness on Exposure],""),IF(OR(_xlpm.v="High effectiveness",_xlpm.v="Medium effectiveness",_xlpm.v="Low effectiveness",_xlpm.e="High effectiveness",_xlpm.e="Medium effectiveness",_xlpm.e="Low effectiveness"),"Yes","")),"") | I7: =IFERROR(_xlfn.LET(_xlpm.v,_xlfn.XLOOKUP(tbl_Summary_Linkage[[#This Row],[ActionID]],tbl_B_Assessment[ActionID],tbl_B_Assessment[Effectiveness on Vulnerability],""),_xlpm.e,_xlfn.XLOOKUP(tbl_Summary_Linkage[[#This Row],[ActionID]],tbl_B_Assessment[ActionID],tbl_B_Assessment[Effectiveness on Exposure],""),IF(OR(_xlpm.v="High effectiveness",_xlpm.v="Medium effectiveness",_xlpm.v="Low effectiveness",_xlpm.e="High effectiveness",_xlpm.e="Medium effectiveness",_xlpm.e="Low effectiveness"),"Yes","")),"")
B8: c40_0052 | C8: Deploy cool pavements and cool roofs on heat‑exposed streets and buildings | D8: =IFERROR(_xlfn.LET(_xlpm.v,_xlfn.XLOOKUP(tbl_Summary_Linkage[[#This Row],[ActionID]],tbl_WR_Assessment[ActionID],tbl_WR_Assessment[Effectiveness on Vulnerability],""),_xlpm.e,_xlfn.XLOOKUP(tbl_Summary_Linkage[[#This Row],[ActionID]],tbl_WR_Assessment[ActionID],tbl_WR_Assessment[Effectiveness on Exposure],""),IF(OR(_xlpm.v="High effectiveness",_xlpm.v="Medium effectiveness",_xlpm.v="Low effectiveness",_xlpm.e="High effectiveness",_xlpm.e="Medium effectiveness",_xlpm.e="Low effectiveness"),"Yes","")),"") | E8: =IFERROR(_xlfn.LET(_xlpm.v,_xlfn.XLOOKUP(tbl_Summary_Linkage[[#This Row],[ActionID]],tbl_FS_Assessment[ActionID],tbl_FS_Assessment[Effectiveness on Vulnerability],""),_xlpm.e,_xlfn.XLOOKUP(tbl_Summary_Linkage[[#This Row],[ActionID]],tbl_FS_Assessment[ActionID],tbl_FS_Assessment[Effectiveness on Exposure],""),IF(OR(_xlpm.v="High effectiveness",_xlpm.v="Medium effectiveness",_xlpm.v="Low effectiveness",_xlpm.e="High effectiveness",_xlpm.e="Medium effectiveness",_xlpm.e="Low effectiveness"),"Yes","")),"") | F8: =IFERROR(_xlfn.LET(_xlpm.v,_xlfn.XLOOKUP(tbl_Summary_Linkage[[#This Row],[ActionID]],tbl_ES_Assessment[ActionID],tbl_ES_Assessment[Effectiveness on Vulnerability],""),_xlpm.e,_xlfn.XLOOKUP(tbl_Summary_Linkage[[#This Row],[ActionID]],tbl_ES_Assessment[ActionID],tbl_ES_Assessment[Effectiveness on Exposure],""),IF(OR(_xlpm.v="High effectiveness",_xlpm.v="Medium effectiveness",_xlpm.v="Low effectiveness",_xlpm.e="High effectiveness",_xlpm.e="Medium effectiveness",_xlpm.e="Low effectiveness"),"Yes","")),"") | G8: =IFERROR(_xlfn.LET(_xlpm.v,_xlfn.XLOOKUP(tbl_Summary_Linkage[[#This Row],[ActionID]],tbl_H_Assessment[ActionID],tbl_H_Assessment[Effectiveness on Vulnerability],""),_xlpm.e,_xlfn.XLOOKUP(tbl_Summary_Linkage[[#This Row],[ActionID]],tbl_H_Assessment[ActionID],tbl_H_Assessment[Effectiveness on Exposure],""),IF(OR(_xlpm.v="High effectiveness",_xlpm.v="Medium effectiveness",_xlpm.v="Low effectiveness",_xlpm.e="High effectiveness",_xlpm.e="Medium effectiveness",_xlpm.e="Low effectiveness"),"Yes","")),"") | H8: =IFERROR(_xlfn.LET(_xlpm.v,_xlfn.XLOOKUP(tbl_Summary_Linkage[[#This Row],[ActionID]],tbl_GS_Assessment[ActionID],tbl_GS_Assessment[Effectiveness on Vulnerability],""),_xlpm.e,_xlfn.XLOOKUP(tbl_Summary_Linkage[[#This Row],[ActionID]],tbl_GS_Assessment[ActionID],tbl_GS_Assessment[Effectiveness on Exposure],""),IF(OR(_xlpm.v="High effectiveness",_xlpm.v="Medium effectiveness",_xlpm.v="Low effectiveness",_xlpm.e="High effectiveness",_xlpm.e="Medium effectiveness",_xlpm.e="Low effectiveness"),"Yes","")),"") | I8: =IFERROR(_xlfn.LET(_xlpm.v,_xlfn.XLOOKUP(tbl_Summary_Linkage[[#This Row],[ActionID]],tbl_B_Assessment[ActionID],tbl_B_Assessment[Effectiveness on Vulnerability],""),_xlpm.e,_xlfn.XLOOKUP(tbl_Summary_Linkage[[#This Row],[ActionID]],tbl_B_Assessment[ActionID],tbl_B_Assessment[Effectiveness on Exposure],""),IF(OR(_xlpm.v="High effectiveness",_xlpm.v="Medium effectiveness",_xlpm.v="Low effectiveness",_xlpm.e="High effectiveness",_xlpm.e="Medium effectiveness",_xlpm.e="Low effectiveness"),"Yes","")),"")
B9: c40_0053 | C9: Promote water-saving technologies and practices | D9: =IFERROR(_xlfn.LET(_xlpm.v,_xlfn.XLOOKUP(tbl_Summary_Linkage[[#This Row],[ActionID]],tbl_WR_Assessment[ActionID],tbl_WR_Assessment[Effectiveness on Vulnerability],""),_xlpm.e,_xlfn.XLOOKUP(tbl_Summary_Linkage[[#This Row],[ActionID]],tbl_WR_Assessment[ActionID],tbl_WR_Assessment[Effectiveness on Exposure],""),IF(OR(_xlpm.v="High effectiveness",_xlpm.v="Medium effectiveness",_xlpm.v="Low effectiveness",_xlpm.e="High effectiveness",_xlpm.e="Medium effectiveness",_xlpm.e="Low effectiveness"),"Yes","")),"") -> Yes | E9: =IFERROR(_xlfn.LET(_xlpm.v,_xlfn.XLOOKUP(tbl_Summary_Linkage[[#This Row],[ActionID]],tbl_FS_Assessment[ActionID],tbl_FS_Assessment[Effectiveness on Vulnerability],""),_xlpm.e,_xlfn.XLOOKUP(tbl_Summary_Linkage[[#This Row],[ActionID]],tbl_FS_Assessment[ActionID],tbl_FS_Assessment[Effectiveness on Exposure],""),IF(OR(_xlpm.v="High effectiveness",_xlpm.v="Medium effectiveness",_xlpm.v="Low effectiveness",_xlpm.e="High effectiveness",_xlpm.e="Medium effectiveness",_xlpm.e="Low effectiveness"),"Yes","")),"") | F9: =IFERROR(_xlfn.LET(_xlpm.v,_xlfn.XLOOKUP(tbl_Summary_Linkage[[#This Row],[ActionID]],tbl_ES_Assessment[ActionID],tbl_ES_Assessment[Effectiveness on Vulnerability],""),_xlpm.e,_xlfn.XLOOKUP(tbl_Summary_Linkage[[#This Row],[ActionID]],tbl_ES_Assessment[ActionID],tbl_ES_Assessment[Effectiveness on Exposure],""),IF(OR(_xlpm.v="High effectiveness",_xlpm.v="Medium effectiveness",_xlpm.v="Low effectiveness",_xlpm.e="High effectiveness",_xlpm.e="Medium effectiveness",_xlpm.e="Low effectiveness"),"Yes","")),"") | G9: =IFERROR(_xlfn.LET(_xlpm.v,_xlfn.XLOOKUP(tbl_Summary_Linkage[[#This Row],[ActionID]],tbl_H_Assessment[ActionID],tbl_H_Assessment[Effectiveness on Vulnerability],""),_xlpm.e,_xlfn.XLOOKUP(tbl_Summary_Linkage[[#This Row],[ActionID]],tbl_H_Assessment[ActionID],tbl_H_Assessment[Effectiveness on Exposure],""),IF(OR(_xlpm.v="High effectiveness",_xlpm.v="Medium effectiveness",_xlpm.v="Low effectiveness",_xlpm.e="High effectiveness",_xlpm.e="Medium effectiveness",_xlpm.e="Low effectiveness"),"Yes","")),"") | H9: =IFERROR(_xlfn.LET(_xlpm.v,_xlfn.XLOOKUP(tbl_Summary_Linkage[[#This Row],[ActionID]],tbl_GS_Assessment[ActionID],tbl_GS_Assessment[Effectiveness on Vulnerability],""),_xlpm.e,_xlfn.XLOOKUP(tbl_Summary_Linkage[[#This Row],[ActionID]],tbl_GS_Assessment[ActionID],tbl_GS_Assessment[Effectiveness on Exposure],""),IF(OR(_xlpm.v="High effectiveness",_xlpm.v="Medium effectiveness",_xlpm.v="Low effectiveness",_xlpm.e="High effectiveness",_xlpm.e="Medium effectiveness",_xlpm.e="Low effectiveness"),"Yes","")),"") | I9: =IFERROR(_xlfn.LET(_xlpm.v,_xlfn.XLOOKUP(tbl_Summary_Linkage[[#This Row],[ActionID]],tbl_B_Assessment[ActionID],tbl_B_Assessment[Effectiveness on Vulnerability],""),_xlpm.e,_xlfn.XLOOKUP(tbl_Summary_Linkage[[#This Row],[ActionID]],tbl_B_Assessment[ActionID],tbl_B_Assessment[Effectiveness on Exposure],""),IF(OR(_xlpm.v="High effectiveness",_xlpm.v="Medium effectiveness",_xlpm.v="Low effectiveness",_xlpm.e="High effectiveness",_xlpm.e="Medium effectiveness",_xlpm.e="Low effectiveness"),"Yes","")),"")
B10: c40_0056 | C10: Improve Watershed Protection and Management | D10: =IFERROR(_xlfn.LET(_xlpm.v,_xlfn.XLOOKUP(tbl_Summary_Linkage[[#This Row],[ActionID]],tbl_WR_Assessment[ActionID],tbl_WR_Assessment[Effectiveness on Vulnerability],""),_xlpm.e,_xlfn.XLOOKUP(tbl_Summary_Linkage[[#This Row],[ActionID]],tbl_WR_Assessment[ActionID],tbl_WR_Assessment[Effectiveness on Exposure],""),IF(OR(_xlpm.v="High effectiveness",_xlpm.v="Medium effectiveness",_xlpm.v="Low effectiveness",_xlpm.e="High effectiveness",_xlpm.e="Medium effectiveness",_xlpm.e="Low effectiveness"),"Yes","")),"") -> Yes | E10: =IFERROR(_xlfn.LET(_xlpm.v,_xlfn.XLOOKUP(tbl_Summary_Linkage[[#This Row],[ActionID]],tbl_FS_Assessment[ActionID],tbl_FS_Assessment[Effectiveness on Vulnerability],""),_xlpm.e,_xlfn.XLOOKUP(tbl_Summary_Linkage[[#This Row],[ActionID]],tbl_FS_Assessment[ActionID],tbl_FS_Assessment[Effectiveness on Exposure],""),IF(OR(_xlpm.v="High effectiveness",_xlpm.v="Medium effectiveness",_xlpm.v="Low effectiveness",_xlpm.e="High effectiveness",_xlpm.e="Medium effectiveness",_xlpm.e="Low effectiveness"),"Yes","")),"") | F10: =IFERROR(_xlfn.LET(_xlpm.v,_xlfn.XLOOKUP(tbl_Summary_Linkage[[#This Row],[ActionID]],tbl_ES_Assessment[ActionID],tbl_ES_Assessment[Effectiveness on Vulnerability],""),_xlpm.e,_xlfn.XLOOKUP(tbl_Summary_Linkage[[#This Row],[ActionID]],tbl_ES_Assessment[ActionID],tbl_ES_Assessment[Effectiveness on Exposure],""),IF(OR(_xlpm.v="High effectiveness",_xlpm.v="Medium effectiveness",_xlpm.v="Low effectiveness",_xlpm.e="High effectiveness",_xlpm.e="Medium effectiveness",_xlpm.e="Low effectiveness"),"Yes","")),"") | G10: =IFERROR(_xlfn.LET(_xlpm.v,_xlfn.XLOOKUP(tbl_Summary_Linkage[[#This Row],[ActionID]],tbl_H_Assessment[ActionID],tbl_H_Assessment[Effectiveness on Vulnerability],""),_xlpm.e,_xlfn.XLOOKUP(tbl_Summary_Linkage[[#This Row],[ActionID]],tbl_H_Assessment[ActionID],tbl_H_Assessment[Effectiveness on Exposure],""),IF(OR(_xlpm.v="High effectiveness",_xlpm.v="Medium effectiveness",_xlpm.v="Low effectiveness",_xlpm.e="High effectiveness",_xlpm.e="Medium effectiveness",_xlpm.e="Low effectiveness"),"Yes","")),"") | H10: =IFERROR(_xlfn.LET(_xlpm.v,_xlfn.XLOOKUP(tbl_Summary_Linkage[[#This Row],[ActionID]],tbl_GS_Assessment[ActionID],tbl_GS_Assessment[Effectiveness on Vulnerability],""),_xlpm.e,_xlfn.XLOOKUP(tbl_Summary_Linkage[[#This Row],[ActionID]],tbl_GS_Assessment[ActionID],tbl_GS_Assessment[Effectiveness on Exposure],""),IF(OR(_xlpm.v="High effectiveness",_xlpm.v="Medium effectiveness",_xlpm.v="Low effectiveness",_xlpm.e="High effectiveness",_xlpm.e="Medium effectiveness",_xlpm.e="Low effectiveness"),"Yes","")),"") | I10: =IFERROR(_xlfn.LET(_xlpm.v,_xlfn.XLOOKUP(tbl_Summary_Linkage[[#This Row],[ActionID]],tbl_B_Assessment[ActionID],tbl_B_Assessment[Effectiveness on Vulnerability],""),_xlpm.e,_xlfn.XLOOKUP(tbl_Summary_Linkage[[#This Row],[ActionID]],tbl_B_Assessment[ActionID],tbl_B_Assessment[Effectiveness on Exposure],""),IF(OR(_xlpm.v="High effectiveness",_xlpm.v="Medium effectiveness",_xlpm.v="Low effectiveness",_xlpm.e="High effectiveness",_xlpm.e="Medium effectiveness",_xlpm.e="Low effectiveness"),"Yes","")),"")
B11: c40_0062 | C11: Reform water tariffs to support efficiency and equity | D11: =IFERROR(_xlfn.LET(_xlpm.v,_xlfn.XLOOKUP(tbl_Summary_Linkage[[#This Row],[ActionID]],tbl_WR_Assessment[ActionID],tbl_WR_Assessment[Effectiveness on Vulnerability],""),_xlpm.e,_xlfn.XLOOKUP(tbl_Summary_Linkage[[#This Row],[ActionID]],tbl_WR_Assessment[ActionID],tbl_WR_Assessment[Effectiveness on Exposure],""),IF(OR(_xlpm.v="High effectiveness",_xlpm.v="Medium effectiveness",_xlpm.v="Low effectiveness",_xlpm.e="High effectiveness",_xlpm.e="Medium effectiveness",_xlpm.e="Low effectiveness"),"Yes","")),"") -> Yes | E11: =IFERROR(_xlfn.LET(_xlpm.v,_xlfn.XLOOKUP(tbl_Summary_Linkage[[#This Row],[ActionID]],tbl_FS_Assessment[ActionID],tbl_FS_Assessment[Effectiveness on Vulnerability],""),_xlpm.e,_xlfn.XLOOKUP(tbl_Summary_Linkage[[#This Row],[ActionID]],tbl_FS_Assessment[ActionID],tbl_FS_Assessment[Effectiveness on Exposure],""),IF(OR(_xlpm.v="High effectiveness",_xlpm.v="Medium effectiveness",_xlpm.v="Low effectiveness",_xlpm.e="High effectiveness",_xlpm.e="Medium effectiveness",_xlpm.e="Low effectiveness"),"Yes","")),"") | F11: =IFERROR(_xlfn.LET(_xlpm.v,_xlfn.XLOOKUP(tbl_Summary_Linkage[[#This Row],[ActionID]],tbl_ES_Assessment[ActionID],tbl_ES_Assessment[Effectiveness on Vulnerability],""),_xlpm.e,_xlfn.XLOOKUP(tbl_Summary_Linkage[[#This Row],[ActionID]],tbl_ES_Assessment[ActionID],tbl_ES_Assessment[Effectiveness on Exposure],""),IF(OR(_xlpm.v="High effectiveness",_xlpm.v="Medium effectiveness",_xlpm.v="Low effectiveness",_xlpm.e="High effectiveness",_xlpm.e="Medium effectiveness",_xlpm.e="Low effectiveness"),"Yes","")),"") | G11: =IFERROR(_xlfn.LET(_xlpm.v,_xlfn.XLOOKUP(tbl_Summary_Linkage[[#This Row],[ActionID]],tbl_H_Assessment[ActionID],tbl_H_Assessment[Effectiveness on Vulnerability],""),_xlpm.e,_xlfn.XLOOKUP(tbl_Summary_Linkage[[#This Row],[ActionID]],tbl_H_Assessment[ActionID],tbl_H_Assessment[Effectiveness on Exposure],""),IF(OR(_xlpm.v="High effectiveness",_xlpm.v="Medium effectiveness",_xlpm.v="Low effectiveness",_xlpm.e="High effectiveness",_xlpm.e="Medium effectiveness",_xlpm.e="Low effectiveness"),"Yes","")),"") | H11: =IFERROR(_xlfn.LET(_xlpm.v,_xlfn.XLOOKUP(tbl_Summary_Linkage[[#This Row],[ActionID]],tbl_GS_Assessment[ActionID],tbl_GS_Assessment[Effectiveness on Vulnerability],""),_xlpm.e,_xlfn.XLOOKUP(tbl_Summary_Linkage[[#This Row],[ActionID]],tbl_GS_Assessment[ActionID],tbl_GS_Assessment[Effectiveness on Exposure],""),IF(OR(_xlpm.v="High effectiveness",_xlpm.v="Medium effectiveness",_xlpm.v="Low effectiveness",_xlpm.e="High effectiveness",_xlpm.e="Medium effectiveness",_xlpm.e="Low effectiveness"),"Yes","")),"") | I11: =IFERROR(_xlfn.LET(_xlpm.v,_xlfn.XLOOKUP(tbl_Summary_Linkage[[#This Row],[ActionID]],tbl_B_Assessment[ActionID],tbl_B_Assessment[Effectiveness on Vulnerability],""),_xlpm.e,_xlfn.XLOOKUP(tbl_Summary_Linkage[[#This Row],[ActionID]],tbl_B_Assessment[ActionID],tbl_B_Assessment[Effectiveness on Exposure],""),IF(OR(_xlpm.v="High effectiveness",_xlpm.v="Medium effectiveness",_xlpm.v="Low effectiveness",_xlpm.e="High effectiveness",_xlpm.e="Medium effectiveness",_xlpm.e="Low effectiveness"),"Yes","")),"")
B12: icare_0144 | C12: Establish a financial support program for extreme weather events | D12: =IFERROR(_xlfn.LET(_xlpm.v,_xlfn.XLOOKUP(tbl_Summary_Linkage[[#This Row],[ActionID]],tbl_WR_Assessment[ActionID],tbl_WR_Assessment[Effectiveness on Vulnerability],""),_xlpm.e,_xlfn.XLOOKUP(tbl_Summary_Linkage[[#This Row],[ActionID]],tbl_WR_Assessment[ActionID],tbl_WR_Assessment[Effectiveness on Exposure],""),IF(OR(_xlpm.v="High effectiveness",_xlpm.v="Medium effectiveness",_xlpm.v="Low effectiveness",_xlpm.e="High effectiveness",_xlpm.e="Medium effectiveness",_xlpm.e="Low effectiveness"),"Yes","")),"") | E12: =IFERROR(_xlfn.LET(_xlpm.v,_xlfn.XLOOKUP(tbl_Summary_Linkage[[#This Row],[ActionID]],tbl_FS_Assessment[ActionID],tbl_FS_Assessment[Effectiveness on Vulnerability],""),_xlpm.e,_xlfn.XLOOKUP(tbl_Summary_Linkage[[#This Row],[ActionID]],tbl_FS_Assessment[ActionID],tbl_FS_Assessment[Effectiveness on Exposure],""),IF(OR(_xlpm.v="High effectiveness",_xlpm.v="Medium effectiveness",_xlpm.v="Low effectiveness",_xlpm.e="High effectiveness",_xlpm.e="Medium effectiveness",_xlpm.e="Low effectiveness"),"Yes","")),"") | F12: =IFERROR(_xlfn.LET(_xlpm.v,_xlfn.XLOOKUP(tbl_Summary_Linkage[[#This Row],[ActionID]],tbl_ES_Assessment[ActionID],tbl_ES_Assessment[Effectiveness on Vulnerability],""),_xlpm.e,_xlfn.XLOOKUP(tbl_Summary_Linkage[[#This Row],[ActionID]],tbl_ES_Assessment[ActionID],tbl_ES_Assessment[Effectiveness on Exposure],""),IF(OR(_xlpm.v="High effectiveness",_xlpm.v="Medium effectiveness",_xlpm.v="Low effectiveness",_xlpm.e="High effectiveness",_xlpm.e="Medium effectiveness",_xlpm.e="Low effectiveness"),"Yes","")),"") | G12: =IFERROR(_xlfn.LET(_xlpm.v,_xlfn.XLOOKUP(tbl_Summary_Linkage[[#This Row],[ActionID]],tbl_H_Assessment[ActionID],tbl_H_Assessment[Effectiveness on Vulnerability],""),_xlpm.e,_xlfn.XLOOKUP(tbl_Summary_Linkage[[#This Row],[ActionID]],tbl_H_Assessment[ActionID],tbl_H_Assessment[Effectiveness on Exposure],""),IF(OR(_xlpm.v="High effectiveness",_xlpm.v="Medium effectiveness",_xlpm.v="Low effectiveness",_xlpm.e="High effectiveness",_xlpm.e="Medium effectiveness",_xlpm.e="Low effectiveness"),"Yes","")),"") | H12: =IFERROR(_xlfn.LET(_xlpm.v,_xlfn.XLOOKUP(tbl_Summary_Linkage[[#This Row],[ActionID]],tbl_GS_Assessment[ActionID],tbl_GS_Assessment[Effectiveness on Vulnerability],""),_xlpm.e,_xlfn.XLOOKUP(tbl_Summary_Linkage[[#This Row],[ActionID]],tbl_GS_Assessment[ActionID],tbl_GS_Assessment[Effectiveness on Exposure],""),IF(OR(_xlpm.v="High effectiveness",_xlpm.v="Medium effectiveness",_xlpm.v="Low effectiveness",_xlpm.e="High effectiveness",_xlpm.e="Medium effectiveness",_xlpm.e="Low effectiveness"),"Yes","")),"") | I12: =IFERROR(_xlfn.LET(_xlpm.v,_xlfn.XLOOKUP(tbl_Summary_Linkage[[#This Row],[ActionID]],tbl_B_Assessment[ActionID],tbl_B_Assessment[Effectiveness on Vulnerability],""),_xlpm.e,_xlfn.XLOOKUP(tbl_Summary_Linkage[[#This Row],[ActionID]],tbl_B_Assessment[ActionID],tbl_B_Assessment[Effectiveness on Exposure],""),IF(OR(_xlpm.v="High effectiveness",_xlpm.v="Medium effectiveness",_xlpm.v="Low effectiveness",_xlpm.e="High effectiveness",_xlpm.e="Medium effectiveness",_xlpm.e="Low effectiveness"),"Yes","")),"")
B13: icare_0145 | C13: Strengthen the healthcare system to respond effectively to extreme events | D13: =IFERROR(_xlfn.LET(_xlpm.v,_xlfn.XLOOKUP(tbl_Summary_Linkage[[#This Row],[ActionID]],tbl_WR_Assessment[ActionID],tbl_WR_Assessment[Effectiveness on Vulnerability],""),_xlpm.e,_xlfn.XLOOKUP(tbl_Summary_Linkage[[#This Row],[ActionID]],tbl_WR_Assessment[ActionID],tbl_WR_Assessment[Effectiveness on Exposure],""),IF(OR(_xlpm.v="High effectiveness",_xlpm.v="Medium effectiveness",_xlpm.v="Low effectiveness",_xlpm.e="High effectiveness",_xlpm.e="Medium effectiveness",_xlpm.e="Low effectiveness"),"Yes","")),"") | E13: =IFERROR(_xlfn.LET(_xlpm.v,_xlfn.XLOOKUP(tbl_Summary_Linkage[[#This Row],[ActionID]],tbl_FS_Assessment[ActionID],tbl_FS_Assessment[Effectiveness on Vulnerability],""),_xlpm.e,_xlfn.XLOOKUP(tbl_Summary_Linkage[[#This Row],[ActionID]],tbl_FS_Assessment[ActionID],tbl_FS_Assessment[Effectiveness on Exposure],""),IF(OR(_xlpm.v="High effectiveness",_xlpm.v="Medium effectiveness",_xlpm.v="Low effectiveness",_xlpm.e="High effectiveness",_xlpm.e="Medium effectiveness",_xlpm.e="Low effectiveness"),"Yes","")),"") | F13: =IFERROR(_xlfn.LET(_xlpm.v,_xlfn.XLOOKUP(tbl_Summary_Linkage[[#This Row],[ActionID]],tbl_ES_Assessment[ActionID],tbl_ES_Assessment[Effectiveness on Vulnerability],""),_xlpm.e,_xlfn.XLOOKUP(tbl_Summary_Linkage[[#This Row],[ActionID]],tbl_ES_Assessment[ActionID],tbl_ES_Assessment[Effectiveness on Exposure],""),IF(OR(_xlpm.v="High effectiveness",_xlpm.v="Medium effectiveness",_xlpm.v="Low effectiveness",_xlpm.e="High effectiveness",_xlpm.e="Medium effectiveness",_xlpm.e="Low effectiveness"),"Yes","")),"") | G13: =IFERROR(_xlfn.LET(_xlpm.v,_xlfn.XLOOKUP(tbl_Summary_Linkage[[#This Row],[ActionID]],tbl_H_Assessment[ActionID],tbl_H_Assessment[Effectiveness on Vulnerability],""),_xlpm.e,_xlfn.XLOOKUP(tbl_Summary_Linkage[[#This Row],[ActionID]],tbl_H_Assessment[ActionID],tbl_H_Assessment[Effectiveness on Exposure],""),IF(OR(_xlpm.v="High effectiveness",_xlpm.v="Medium effectiveness",_xlpm.v="Low effectiveness",_xlpm.e="High effectiveness",_xlpm.e="Medium effectiveness",_xlpm.e="Low effectiveness"),"Yes","")),"") | H13: =IFERROR(_xlfn.LET(_xlpm.v,_xlfn.XLOOKUP(tbl_Summary_Linkage[[#This Row],[ActionID]],tbl_GS_Assessment[ActionID],tbl_GS_Assessment[Effectiveness on Vulnerability],""),_xlpm.e,_xlfn.XLOOKUP(tbl_Summary_Linkage[[#This Row],[ActionID]],tbl_GS_Assessment[ActionID],tbl_GS_Assessment[Effectiveness on Exposure],""),IF(OR(_xlpm.v="High effectiveness",_xlpm.v="Medium effectiveness",_xlpm.v="Low effectiveness",_xlpm.e="High effectiveness",_xlpm.e="Medium effectiveness",_xlpm.e="Low effectiveness"),"Yes","")),"") | I13: =IFERROR(_xlfn.LET(_xlpm.v,_xlfn.XLOOKUP(tbl_Summary_Linkage[[#This Row],[ActionID]],tbl_B_Assessment[ActionID],tbl_B_Assessment[Effectiveness on Vulnerability],""),_xlpm.e,_xlfn.XLOOKUP(tbl_Summary_Linkage[[#This Row],[ActionID]],tbl_B_Assessment[ActionID],tbl_B_Assessment[Effectiveness on Exposure],""),IF(OR(_xlpm.v="High effectiveness",_xlpm.v="Medium effectiveness",_xlpm.v="Low effectiveness",_xlpm.e="High effectiveness",_xlpm.e="Medium effectiveness",_xlpm.e="Low effectiveness"),"Yes","")),"")
B14: icare_0154 | C14: Clean and unclog drainage channels and install eco-barriers | D14: =IFERROR(_xlfn.LET(_xlpm.v,_xlfn.XLOOKUP(tbl_Summary_Linkage[[#This Row],[ActionID]],tbl_WR_Assessment[ActionID],tbl_WR_Assessment[Effectiveness on Vulnerability],""),_xlpm.e,_xlfn.XLOOKUP(tbl_Summary_Linkage[[#This Row],[ActionID]],tbl_WR_Assessment[ActionID],tbl_WR_Assessment[Effectiveness on Exposure],""),IF(OR(_xlpm.v="High effectiveness",_xlpm.v="Medium effectiveness",_xlpm.v="Low effectiveness",_xlpm.e="High effectiveness",_xlpm.e="Medium effectiveness",_xlpm.e="Low effectiveness"),"Yes","")),"") | E14: =IFERROR(_xlfn.LET(_xlpm.v,_xlfn.XLOOKUP(tbl_Summary_Linkage[[#This Row],[ActionID]],tbl_FS_Assessment[ActionID],tbl_FS_Assessment[Effectiveness on Vulnerability],""),_xlpm.e,_xlfn.XLOOKUP(tbl_Summary_Linkage[[#This Row],[ActionID]],tbl_FS_Assessment[ActionID],tbl_FS_Assessment[Effectiveness on Exposure],""),IF(OR(_xlpm.v="High effectiveness",_xlpm.v="Medium effectiveness",_xlpm.v="Low effectiveness",_xlpm.e="High effectiveness",_xlpm.e="Medium effectiveness",_xlpm.e="Low effectiveness"),"Yes","")),"") | F14: =IFERROR(_xlfn.LET(_xlpm.v,_xlfn.XLOOKUP(tbl_Summary_Linkage[[#This Row],[ActionID]],tbl_ES_Assessment[ActionID],tbl_ES_Assessment[Effectiveness on Vulnerability],""),_xlpm.e,_xlfn.XLOOKUP(tbl_Summary_Linkage[[#This Row],[ActionID]],tbl_ES_Assessment[ActionID],tbl_ES_Assessment[Effectiveness on Exposure],""),IF(OR(_xlpm.v="High effectiveness",_xlpm.v="Medium effectiveness",_xlpm.v="Low effectiveness",_xlpm.e="High effectiveness",_xlpm.e="Medium effectiveness",_xlpm.e="Low effectiveness"),"Yes","")),"") | G14: =IFERROR(_xlfn.LET(_xlpm.v,_xlfn.XLOOKUP(tbl_Summary_Linkage[[#This Row],[ActionID]],tbl_H_Assessment[ActionID],tbl_H_Assessment[Effectiveness on Vulnerability],""),_xlpm.e,_xlfn.XLOOKUP(tbl_Summary_Linkage[[#This Row],[ActionID]],tbl_H_Assessment[ActionID],tbl_H_Assessment[Effectiveness on Exposure],""),IF(OR(_xlpm.v="High effectiveness",_xlpm.v="Medium effectiveness",_xlpm.v="Low effectiveness",_xlpm.e="High effectiveness",_xlpm.e="Medium effectiveness",_xlpm.e="Low effectiveness"),"Yes","")),"") | H14: =IFERROR(_xlfn.LET(_xlpm.v,_xlfn.XLOOKUP(tbl_Summary_Linkage[[#This Row],[ActionID]],tbl_GS_Assessment[ActionID],tbl_GS_Assessment[Effectiveness on Vulnerability],""),_xlpm.e,_xlfn.XLOOKUP(tbl_Summary_Linkage[[#This Row],[ActionID]],tbl_GS_Assessment[ActionID],tbl_GS_Assessment[Effectiveness on Exposure],""),IF(OR(_xlpm.v="High effectiveness",_xlpm.v="Medium effectiveness",_xlpm.v="Low effectiveness",_xlpm.e="High effectiveness",_xlpm.e="Medium effectiveness",_xlpm.e="Low effectiveness"),"Yes","")),"") | I14: =IFERROR(_xlfn.LET(_xlpm.v,_xlfn.XLOOKUP(tbl_Summary_Linkage[[#This Row],[ActionID]],tbl_B_Assessment[ActionID],tbl_B_Assessment[Effectiveness on Vulnerability],""),_xlpm.e,_xlfn.XLOOKUP(tbl_Summary_Linkage[[#This Row],[ActionID]],tbl_B_Assessment[ActionID],tbl_B_Assessment[Effectiveness on Exposure],""),IF(OR(_xlpm.v="High effectiveness",_xlpm.v="Medium effectiveness",_xlpm.v="Low effectiveness",_xlpm.e="High effectiveness",_xlpm.e="Medium effectiveness",_xlpm.e="Low effectiveness"),"Yes","")),"")
B15: icare_0156 | C15: Improve Implementation of urban gardens | D15: =IFERROR(_xlfn.LET(_xlpm.v,_xlfn.XLOOKUP(tbl_Summary_Linkage[[#This Row],[ActionID]],tbl_WR_Assessment[ActionID],tbl_WR_Assessment[Effectiveness on Vulnerability],""),_xlpm.e,_xlfn.XLOOKUP(tbl_Summary_Linkage[[#This Row],[ActionID]],tbl_WR_Assessment[ActionID],tbl_WR_Assessment[Effectiveness on Exposure],""),IF(OR(_xlpm.v="High effectiveness",_xlpm.v="Medium effectiveness",_xlpm.v="Low effectiveness",_xlpm.e="High effectiveness",_xlpm.e="Medium effectiveness",_xlpm.e="Low effectiveness"),"Yes","")),"") | E15: =IFERROR(_xlfn.LET(_xlpm.v,_xlfn.XLOOKUP(tbl_Summary_Linkage[[#This Row],[ActionID]],tbl_FS_Assessment[ActionID],tbl_FS_Assessment[Effectiveness on Vulnerability],""),_xlpm.e,_xlfn.XLOOKUP(tbl_Summary_Linkage[[#This Row],[ActionID]],tbl_FS_Assessment[ActionID],tbl_FS_Assessment[Effectiveness on Exposure],""),IF(OR(_xlpm.v="High effectiveness",_xlpm.v="Medium effectiveness",_xlpm.v="Low effectiveness",_xlpm.e="High effectiveness",_xlpm.e="Medium effectiveness",_xlpm.e="Low effectiveness"),"Yes","")),"") | F15: =IFERROR(_xlfn.LET(_xlpm.v,_xlfn.XLOOKUP(tbl_Summary_Linkage[[#This Row],[ActionID]],tbl_ES_Assessment[ActionID],tbl_ES_Assessment[Effectiveness on Vulnerability],""),_xlpm.e,_xlfn.XLOOKUP(tbl_Summary_Linkage[[#This Row],[ActionID]],tbl_ES_Assessment[ActionID],tbl_ES_Assessment[Effectiveness on Exposure],""),IF(OR(_xlpm.v="High effectiveness",_xlpm.v="Medium effectiveness",_xlpm.v="Low effectiveness",_xlpm.e="High effectiveness",_xlpm.e="Medium effectiveness",_xlpm.e="Low effectiveness"),"Yes","")),"") | G15: =IFERROR(_xlfn.LET(_xlpm.v,_xlfn.XLOOKUP(tbl_Summary_Linkage[[#This Row],[ActionID]],tbl_H_Assessment[ActionID],tbl_H_Assessment[Effectiveness on Vulnerability],""),_xlpm.e,_xlfn.XLOOKUP(tbl_Summary_Linkage[[#This Row],[ActionID]],tbl_H_Assessment[ActionID],tbl_H_Assessment[Effectiveness on Exposure],""),IF(OR(_xlpm.v="High effectiveness",_xlpm.v="Medium effectiveness",_xlpm.v="Low effectiveness",_xlpm.e="High effectiveness",_xlpm.e="Medium effectiveness",_xlpm.e="Low effectiveness"),"Yes","")),"") | H15: =IFERROR(_xlfn.LET(_xlpm.v,_xlfn.XLOOKUP(tbl_Summary_Linkage[[#This Row],[ActionID]],tbl_GS_Assessment[ActionID],tbl_GS_Assessment[Effectiveness on Vulnerability],""),_xlpm.e,_xlfn.XLOOKUP(tbl_Summary_Linkage[[#This Row],[ActionID]],tbl_GS_Assessment[ActionID],tbl_GS_Assessment[Effectiveness on Exposure],""),IF(OR(_xlpm.v="High effectiveness",_xlpm.v="Medium effectiveness",_xlpm.v="Low effectiveness",_xlpm.e="High effectiveness",_xlpm.e="Medium effectiveness",_xlpm.e="Low effectiveness"),"Yes","")),"") | I15: =IFERROR(_xlfn.LET(_xlpm.v,_xlfn.XLOOKUP(tbl_Summary_Linkage[[#This Row],[ActionID]],tbl_B_Assessment[ActionID],tbl_B_Assessment[Effectiveness on Vulnerability],""),_xlpm.e,_xlfn.XLOOKUP(tbl_Summary_Linkage[[#This Row],[ActionID]],tbl_B_Assessment[ActionID],tbl_B_Assessment[Effectiveness on Exposure],""),IF(OR(_xlpm.v="High effectiveness",_xlpm.v="Medium effectiveness",_xlpm.v="Low effectiveness",_xlpm.e="High effectiveness",_xlpm.e="Medium effectiveness",_xlpm.e="Low effectiveness"),"Yes","")),"")
... B56: ipcc_0104 | C56: Plan and support permanent climate‑related migration | D56: =IFERROR(_xlfn.LET(_xlpm.v,_xlfn.XLOOKUP(tbl_Summary_Linkage[[#This Row],[ActionID]],tbl_WR_Assessment[ActionID],tbl_WR_Assessment[Effectiveness on Vulnerability],""),_xlpm.e,_xlfn.XLOOKUP(tbl_Summary_Linkage[[#This Row],[ActionID]],tbl_WR_Assessment[ActionID],tbl_WR_Assessment[Effectiveness on Exposure],""),IF(OR(_xlpm.v="High effectiveness",_xlpm.v="Medium effectiveness",_xlpm.v="Low effectiveness",_xlpm.e="High effectiveness",_xlpm.e="Medium effectiveness",_xlpm.e="Low effectiveness"),"Yes","")),"") | E56: =IFERROR(_xlfn.LET(_xlpm.v,_xlfn.XLOOKUP(tbl_Summary_Linkage[[#This Row],[ActionID]],tbl_FS_Assessment[ActionID],tbl_FS_Assessment[Effectiveness on Vulnerability],""),_xlpm.e,_xlfn.XLOOKUP(tbl_Summary_Linkage[[#This Row],[ActionID]],tbl_FS_Assessment[ActionID],tbl_FS_Assessment[Effectiveness on Exposure],""),IF(OR(_xlpm.v="High effectiveness",_xlpm.v="Medium effectiveness",_xlpm.v="Low effectiveness",_xlpm.e="High effectiveness",_xlpm.e="Medium effectiveness",_xlpm.e="Low effectiveness"),"Yes","")),"") | F56: =IFERROR(_xlfn.LET(_xlpm.v,_xlfn.XLOOKUP(tbl_Summary_Linkage[[#This Row],[ActionID]],tbl_ES_Assessment[ActionID],tbl_ES_Assessment[Effectiveness on Vulnerability],""),_xlpm.e,_xlfn.XLOOKUP(tbl_Summary_Linkage[[#This Row],[ActionID]],tbl_ES_Assessment[ActionID],tbl_ES_Assessment[Effectiveness on Exposure],""),IF(OR(_xlpm.v="High effectiveness",_xlpm.v="Medium effectiveness",_xlpm.v="Low effectiveness",_xlpm.e="High effectiveness",_xlpm.e="Medium effectiveness",_xlpm.e="Low effectiveness"),"Yes","")),"") | G56: =IFERROR(_xlfn.LET(_xlpm.v,_xlfn.XLOOKUP(tbl_Summary_Linkage[[#This Row],[ActionID]],tbl_H_Assessment[ActionID],tbl_H_Assessment[Effectiveness on Vulnerability],""),_xlpm.e,_xlfn.XLOOKUP(tbl_Summary_Linkage[[#This Row],[ActionID]],tbl_H_Assessment[ActionID],tbl_H_Assessment[Effectiveness on Exposure],""),IF(OR(_xlpm.v="High effectiveness",_xlpm.v="Medium effectiveness",_xlpm.v="Low effectiveness",_xlpm.e="High effectiveness",_xlpm.e="Medium effectiveness",_xlpm.e="Low effectiveness"),"Yes","")),"") | H56: =IFERROR(_xlfn.LET(_xlpm.v,_xlfn.XLOOKUP(tbl_Summary_Linkage[[#This Row],[ActionID]],tbl_GS_Assessment[ActionID],tbl_GS_Assessment[Effectiveness on Vulnerability],""),_xlpm.e,_xlfn.XLOOKUP(tbl_Summary_Linkage[[#This Row],[ActionID]],tbl_GS_Assessment[ActionID],tbl_GS_Assessment[Effectiveness on Exposure],""),IF(OR(_xlpm.v="High effectiveness",_xlpm.v="Medium effectiveness",_xlpm.v="Low effectiveness",_xlpm.e="High effectiveness",_xlpm.e="Medium effectiveness",_xlpm.e="Low effectiveness"),"Yes","")),"") | I56: =IFERROR(_xlfn.LET(_xlpm.v,_xlfn.XLOOKUP(tbl_Summary_Linkage[[#This Row],[ActionID]],tbl_B_Assessment[ActionID],tbl_B_Assessment[Effectiveness on Vulnerability],""),_xlpm.e,_xlfn.XLOOKUP(tbl_Summary_Linkage[[#This Row],[ActionID]],tbl_B_Assessment[ActionID],tbl_B_Assessment[Effectiveness on Exposure],""),IF(OR(_xlpm.v="High effectiveness",_xlpm.v="Medium effectiveness",_xlpm.v="Low effectiveness",_xlpm.e="High effectiveness",_xlpm.e="Medium effectiveness",_xlpm.e="Low effectiveness"),"Yes","")),"")
B59: PARAMETER TABLE
B60: Parameter | C60: Default value
B61: High effectiveness | C61: -1
B62: Medium effectiveness | C62: -0.5
B63: Low effectiveness | C63: -0.25
B64: No effectiveness | C64: 0
B67: SUMMARY MATRIX
B68: ActionID | C68: ActionName | D68: Water Resources - Effectiveness on Vulnerability | E68: Water Resources - Effectiveness on Exposure | F68: Food Security - Effectiveness on Vulnerability | G68: Food Security - Effectiveness on Exposure | H68: Energy Security - Effectiveness on Vulnerability | I68: Energy Security - Effectiveness on Exposure | J68: Health - Effectiveness on Vulnerability | K68: Health - Effectiveness on Exposure | L68: Geohydrological Disasters - Effectiveness on Vulnerability | M68: Geohydrological Disasters - Effectiveness on Exposure | N68: Biodiversity - Effectiveness on Vulnerability | O68: Biodiversity - Effectiveness on Exposure
B69: c40_0046 | C69: Strengthen coastal protection infrastructure | D69: =IFERROR(IF(_xlfn.XLOOKUP(tbl_Summary_Numerical[[#This Row],[ActionID]],tbl_WR_EligibilitySummary[Action ID],tbl_WR_EligibilitySummary[Vulnerability Eligibility],"")="Eligible",_xlfn.XLOOKUP(_xlfn.XLOOKUP(tbl_Summary_Numerical[[#This Row],[ActionID]],tbl_WR_Assessment[ActionID],tbl_WR_Assessment[Effectiveness on Vulnerability],""),'Summary Matrix'!$B$61:$B$64,'Summary Matrix'!$C$61:$C$64,""),""),"") | E69: =IFERROR(IF(_xlfn.XLOOKUP(tbl_Summary_Numerical[[#This Row],[ActionID]],tbl_WR_EligibilitySummary[Action ID],tbl_WR_EligibilitySummary[Exposure Eligibility],"")="Eligible",_xlfn.XLOOKUP(_xlfn.XLOOKUP(tbl_Summary_Numerical[[#This Row],[ActionID]],tbl_WR_Assessment[ActionID],tbl_WR_Assessment[Effectiveness on Exposure],""),'Summary Matrix'!$B$61:$B$64,'Summary Matrix'!$C$61:$C$64,""),""),"") | F69: =IFERROR(IF(_xlfn.XLOOKUP(tbl_Summary_Numerical[[#This Row],[ActionID]],tbl_FS_EligibilitySummary[Action ID],tbl_FS_EligibilitySummary[Vulnerability Eligibility],"")="Eligible",_xlfn.XLOOKUP(_xlfn.XLOOKUP(tbl_Summary_Numerical[[#This Row],[ActionID]],tbl_FS_Assessment[ActionID],tbl_FS_Assessment[Effectiveness on Vulnerability],""),'Summary Matrix'!$B$61:$B$64,'Summary Matrix'!$C$61:$C$64,""),""),"") | G69: =IFERROR(IF(_xlfn.XLOOKUP(tbl_Summary_Numerical[[#This Row],[ActionID]],tbl_FS_EligibilitySummary[Action ID],tbl_FS_EligibilitySummary[Exposure Eligibility],"")="Eligible",_xlfn.XLOOKUP(_xlfn.XLOOKUP(tbl_Summary_Numerical[[#This Row],[ActionID]],tbl_FS_Assessment[ActionID],tbl_FS_Assessment[Effectiveness on Exposure],""),'Summary Matrix'!$B$61:$B$64,'Summary Matrix'!$C$61:$C$64,""),""),"") | H69: =IFERROR(IF(_xlfn.XLOOKUP(tbl_Summary_Numerical[[#This Row],[ActionID]],tbl_ES_EligibilitySummary[Action ID],tbl_ES_EligibilitySummary[Vulnerability Eligibility],"")="Eligible",_xlfn.XLOOKUP(_xlfn.XLOOKUP(tbl_Summary_Numerical[[#This Row],[ActionID]],tbl_ES_Assessment[ActionID],tbl_ES_Assessment[Effectiveness on Vulnerability],""),'Summary Matrix'!$B$61:$B$64,'Summary Matrix'!$C$61:$C$64,""),""),"") | I69: =IFERROR(IF(_xlfn.XLOOKUP(tbl_Summary_Numerical[[#This Row],[ActionID]],tbl_ES_EligibilitySummary[Action ID],tbl_ES_EligibilitySummary[Exposure Eligibility],"")="Eligible",_xlfn.XLOOKUP(_xlfn.XLOOKUP(tbl_Summary_Numerical[[#This Row],[ActionID]],tbl_ES_Assessment[ActionID],tbl_ES_Assessment[Effectiveness on Exposure],""),'Summary Matrix'!$B$61:$B$64,'Summary Matrix'!$C$61:$C$64,""),""),"") | J69: =IFERROR(IF(_xlfn.XLOOKUP(tbl_Summary_Numerical[[#This Row],[ActionID]],tbl_H_EligibilitySummary[Action ID],tbl_H_EligibilitySummary[Vulnerability Eligibility],"")="Eligible",_xlfn.XLOOKUP(_xlfn.XLOOKUP(tbl_Summary_Numerical[[#This Row],[ActionID]],tbl_H_Assessment[ActionID],tbl_H_Assessment[Effectiveness on Vulnerability],""),'Summary Matrix'!$B$61:$B$64,'Summary Matrix'!$C$61:$C$64,""),""),"") | K69: =IFERROR(IF(_xlfn.XLOOKUP(tbl_Summary_Numerical[[#This Row],[ActionID]],tbl_H_EligibilitySummary[Action ID],tbl_H_EligibilitySummary[Exposure Eligibility],"")="Eligible",_xlfn.XLOOKUP(_xlfn.XLOOKUP(tbl_Summary_Numerical[[#This Row],[ActionID]],tbl_H_Assessment[ActionID],tbl_H_Assessment[Effectiveness on Exposure],""),'Summary Matrix'!$B$61:$B$64,'Summary Matrix'!$C$61:$C$64,""),""),"") | L69: =IFERROR(IF(_xlfn.XLOOKUP(tbl_Summary_Numerical[[#This Row],[ActionID]],tbl_GS_EligibilitySummary[Action ID],tbl_GS_EligibilitySummary[Vulnerability Eligibility],"")="Eligible",_xlfn.XLOOKUP(_xlfn.XLOOKUP(tbl_Summary_Numerical[[#This Row],[ActionID]],tbl_GS_Assessment[ActionID],tbl_GS_Assessment[Effectiveness on Vulnerability],""),'Summary Matrix'!$B$61:$B$64,'Summary Matrix'!$C$61:$C$64,""),""),"") | M69: =IFERROR(IF(_xlfn.XLOOKUP(tbl_Summary_Numerical[[#This Row],[ActionID]],tbl_GS_EligibilitySummary[Action ID],tbl_GS_EligibilitySummary[Exposure Eligibility],"")="Eligible",_xlfn.XLOOKUP(_xlfn.XLOOKUP(tbl_Summary_Numerical[[#This Row],[ActionID]],tbl_GS_Assessment[ActionID],tbl_GS_Assessment[Effectiveness on Exposure],""),'Summary Matrix'!$B$61:$B$64,'Summary Matrix'!$C$61:$C$64,""),""),"") | N69: =IFERROR(IF(_xlfn.XLOOKUP(tbl_Summary_Numerical[[#This Row],[ActionID]],tbl_B_EligibilitySummary[Action ID],tbl_B_EligibilitySummary[Vulnerability Eligibility],"")="Eligible",_xlfn.XLOOKUP(_xlfn.XLOOKUP(tbl_Summary_Numerical[[#This Row],[ActionID]],tbl_B_Assessment[ActionID],tbl_B_Assessment[Effectiveness on Vulnerability],""),'Summary Matrix'!$B$61:$B$64,'Summary Matrix'!$C$61:$C$64,""),""),"") | O69: =IFERROR(IF(_xlfn.XLOOKUP(tbl_Summary_Numerical[[#This Row],[ActionID]],tbl_B_EligibilitySummary[Action ID],tbl_B_EligibilitySummary[Exposure Eligibility],"")="Eligible",_xlfn.XLOOKUP(_xlfn.XLOOKUP(tbl_Summary_Numerical[[#This Row],[ActionID]],tbl_B_Assessment[ActionID],tbl_B_Assessment[Effectiveness on Exposure],""),'Summary Matrix'!$B$61:$B$64,'Summary Matrix'!$C$61:$C$64,""),""),"")
B70: c40_0048 | C70: Upgrade urban drainage systems | D70: =IFERROR(IF(_xlfn.XLOOKUP(tbl_Summary_Numerical[[#This Row],[ActionID]],tbl_WR_EligibilitySummary[Action ID],tbl_WR_EligibilitySummary[Vulnerability Eligibility],"")="Eligible",_xlfn.XLOOKUP(_xlfn.XLOOKUP(tbl_Summary_Numerical[[#This Row],[ActionID]],tbl_WR_Assessment[ActionID],tbl_WR_Assessment[Effectiveness on Vulnerability],""),'Summary Matrix'!$B$61:$B$64,'Summary Matrix'!$C$61:$C$64,""),""),"") | E70: =IFERROR(IF(_xlfn.XLOOKUP(tbl_Summary_Numerical[[#This Row],[ActionID]],tbl_WR_EligibilitySummary[Action ID],tbl_WR_EligibilitySummary[Exposure Eligibility],"")="Eligible",_xlfn.XLOOKUP(_xlfn.XLOOKUP(tbl_Summary_Numerical[[#This Row],[ActionID]],tbl_WR_Assessment[ActionID],tbl_WR_Assessment[Effectiveness on Exposure],""),'Summary Matrix'!$B$61:$B$64,'Summary Matrix'!$C$61:$C$64,""),""),"") | F70: =IFERROR(IF(_xlfn.XLOOKUP(tbl_Summary_Numerical[[#This Row],[ActionID]],tbl_FS_EligibilitySummary[Action ID],tbl_FS_EligibilitySummary[Vulnerability Eligibility],"")="Eligible",_xlfn.XLOOKUP(_xlfn.XLOOKUP(tbl_Summary_Numerical[[#This Row],[ActionID]],tbl_FS_Assessment[ActionID],tbl_FS_Assessment[Effectiveness on Vulnerability],""),'Summary Matrix'!$B$61:$B$64,'Summary Matrix'!$C$61:$C$64,""),""),"") | G70: =IFERROR(IF(_xlfn.XLOOKUP(tbl_Summary_Numerical[[#This Row],[ActionID]],tbl_FS_EligibilitySummary[Action ID],tbl_FS_EligibilitySummary[Exposure Eligibility],"")="Eligible",_xlfn.XLOOKUP(_xlfn.XLOOKUP(tbl_Summary_Numerical[[#This Row],[ActionID]],tbl_FS_Assessment[ActionID],tbl_FS_Assessment[Effectiveness on Exposure],""),'Summary Matrix'!$B$61:$B$64,'Summary Matrix'!$C$61:$C$64,""),""),"") | H70: =IFERROR(IF(_xlfn.XLOOKUP(tbl_Summary_Numerical[[#This Row],[ActionID]],tbl_ES_EligibilitySummary[Action ID],tbl_ES_EligibilitySummary[Vulnerability Eligibility],"")="Eligible",_xlfn.XLOOKUP(_xlfn.XLOOKUP(tbl_Summary_Numerical[[#This Row],[ActionID]],tbl_ES_Assessment[ActionID],tbl_ES_Assessment[Effectiveness on Vulnerability],""),'Summary Matrix'!$B$61:$B$64,'Summary Matrix'!$C$61:$C$64,""),""),"") | I70: =IFERROR(IF(_xlfn.XLOOKUP(tbl_Summary_Numerical[[#This Row],[ActionID]],tbl_ES_EligibilitySummary[Action ID],tbl_ES_EligibilitySummary[Exposure Eligibility],"")="Eligible",_xlfn.XLOOKUP(_xlfn.XLOOKUP(tbl_Summary_Numerical[[#This Row],[ActionID]],tbl_ES_Assessment[ActionID],tbl_ES_Assessment[Effectiveness on Exposure],""),'Summary Matrix'!$B$61:$B$64,'Summary Matrix'!$C$61:$C$64,""),""),"") | J70: =IFERROR(IF(_xlfn.XLOOKUP(tbl_Summary_Numerical[[#This Row],[ActionID]],tbl_H_EligibilitySummary[Action ID],tbl_H_EligibilitySummary[Vulnerability Eligibility],"")="Eligible",_xlfn.XLOOKUP(_xlfn.XLOOKUP(tbl_Summary_Numerical[[#This Row],[ActionID]],tbl_H_Assessment[ActionID],tbl_H_Assessment[Effectiveness on Vulnerability],""),'Summary Matrix'!$B$61:$B$64,'Summary Matrix'!$C$61:$C$64,""),""),"") | K70: =IFERROR(IF(_xlfn.XLOOKUP(tbl_Summary_Numerical[[#This Row],[ActionID]],tbl_H_EligibilitySummary[Action ID],tbl_H_EligibilitySummary[Exposure Eligibility],"")="Eligible",_xlfn.XLOOKUP(_xlfn.XLOOKUP(tbl_Summary_Numerical[[#This Row],[ActionID]],tbl_H_Assessment[ActionID],tbl_H_Assessment[Effectiveness on Exposure],""),'Summary Matrix'!$B$61:$B$64,'Summary Matrix'!$C$61:$C$64,""),""),"") | L70: =IFERROR(IF(_xlfn.XLOOKUP(tbl_Summary_Numerical[[#This Row],[ActionID]],tbl_GS_EligibilitySummary[Action ID],tbl_GS_EligibilitySummary[Vulnerability Eligibility],"")="Eligible",_xlfn.XLOOKUP(_xlfn.XLOOKUP(tbl_Summary_Numerical[[#This Row],[ActionID]],tbl_GS_Assessment[ActionID],tbl_GS_Assessment[Effectiveness on Vulnerability],""),'Summary Matrix'!$B$61:$B$64,'Summary Matrix'!$C$61:$C$64,""),""),"") | M70: =IFERROR(IF(_xlfn.XLOOKUP(tbl_Summary_Numerical[[#This Row],[ActionID]],tbl_GS_EligibilitySummary[Action ID],tbl_GS_EligibilitySummary[Exposure Eligibility],"")="Eligible",_xlfn.XLOOKUP(_xlfn.XLOOKUP(tbl_Summary_Numerical[[#This Row],[ActionID]],tbl_GS_Assessment[ActionID],tbl_GS_Assessment[Effectiveness on Exposure],""),'Summary Matrix'!$B$61:$B$64,'Summary Matrix'!$C$61:$C$64,""),""),"") | N70: =IFERROR(IF(_xlfn.XLOOKUP(tbl_Summary_Numerical[[#This Row],[ActionID]],tbl_B_EligibilitySummary[Action ID],tbl_B_EligibilitySummary[Vulnerability Eligibility],"")="Eligible",_xlfn.XLOOKUP(_xlfn.XLOOKUP(tbl_Summary_Numerical[[#This Row],[ActionID]],tbl_B_Assessment[ActionID],tbl_B_Assessment[Effectiveness on Vulnerability],""),'Summary Matrix'!$B$61:$B$64,'Summary Matrix'!$C$61:$C$64,""),""),"") | O70: =IFERROR(IF(_xlfn.XLOOKUP(tbl_Summary_Numerical[[#This Row],[ActionID]],tbl_B_EligibilitySummary[Action ID],tbl_B_EligibilitySummary[Exposure Eligibility],"")="Eligible",_xlfn.XLOOKUP(_xlfn.XLOOKUP(tbl_Summary_Numerical[[#This Row],[ActionID]],tbl_B_Assessment[ActionID],tbl_B_Assessment[Effectiveness on Exposure],""),'Summary Matrix'!$B$61:$B$64,'Summary Matrix'!$C$61:$C$64,""),""),"")
