Workbook

Sheet Readme
B2: Description | C2: This file describes the list of shifts from TEF that can be included or removed for the City Compass.
C3: It also lists shifts that are not currently included in the TEF.
B5: File provider | C5: Honorine
B6: Date | C6: 46212
B8: Reference | C8: TEF | D8: https://www.transitionelements.org/3-transition-elements/
C9: Pathways | D9: https://www.c40knowledgehub.org/s/article/Pathways-Air-Quality-Pathways-AQ?language=en_US
C10: Climate Trace | D10: https://climatetrace.org/reduce/city/ghs-fua_2702/Paris-Urban-Area%2C-FRA
D13: Total | E13: Transport | F13: Industrial | G13: Residential | H13: Non residential | I13: Generation | J13: Solid Waste | K13: AFOLU | M13: Road | N13: Aviation | O13: Commercial | P13: Rail | Q13: Water
C14: Number of shifts | D14: =COUNTA('TEF shifts'!A:A)-1 -> 282 | E14: =SUM(M14:Q14) -> 84 | F14: =COUNTIFS('TEF shifts'!$C:$C,F$13) -> 37 | G14: =COUNTIFS('TEF shifts'!$C:$C,G$13) -> 41 | H14: =COUNTIFS('TEF shifts'!$C:$C,H$13) -> 45 | I14: =COUNTIFS('TEF shifts'!$C:$C,I$13) -> 33 | J14: =COUNTIFS('TEF shifts'!$C:$C,J$13) -> 23 | K14: =COUNTIFS('TEF shifts'!$C:$C,K$13) -> 14 | M14: =COUNTIFS('TEF shifts'!$C:$C,M$13) -> 58 | N14: =COUNTIFS('TEF shifts'!$C:$C,N$13) -> 8 | O14: =COUNTIFS('TEF shifts'!$C:$C,O$13) -> 0 | P14: =COUNTIFS('TEF shifts'!$C:$C,P$13) -> 7 | Q14: =COUNTIFS('TEF shifts'!$C:$C,Q$13) -> 11
C15: Shifts to be used | D15: =COUNTIFS('TEF shifts'!J:J,"Include") -> 119 | E15: =SUM(M15:Q15)/E$14 -> 0.46428571 | F15: =COUNTIFS('TEF shifts'!$J:$J,"Include",'TEF shifts'!$C:$C,F$13)/F$14 -> 0.27027027 | G15: =COUNTIFS('TEF shifts'!$J:$J,"Include",'TEF shifts'!$C:$C,G$13)/G$14 -> 0.43902439 | H15: =COUNTIFS('TEF shifts'!$J:$J,"Include",'TEF shifts'!$C:$C,H$13)/H$14 -> 0.53333333 | I15: =COUNTIFS('TEF shifts'!$J:$J,"Include",'TEF shifts'!$C:$C,I$13)/I$14 -> 0.72727273 | J15: =COUNTIFS('TEF shifts'!$J:$J,"Include",'TEF shifts'!$C:$C,J$13)/J$14 -> 0.17391304 | K15: =COUNTIFS('TEF shifts'!$J:$J,"Include",'TEF shifts'!$C:$C,K$13)/K$14 -> 0 | M15: =COUNTIFS('TEF shifts'!$J:$J,"Include",'TEF shifts'!$C:$C,M$13) -> 27 | N15: =COUNTIFS('TEF shifts'!$J:$J,"Include",'TEF shifts'!$C:$C,N$13) -> 6 | O15: =COUNTIFS('TEF shifts'!$J:$J,"Include",'TEF shifts'!$C:$C,O$13) -> 0 | P15: =COUNTIFS('TEF shifts'!$J:$J,"Include",'TEF shifts'!$C:$C,P$13) -> 2 | Q15: =COUNTIFS('TEF shifts'!$J:$J,"Include",'TEF shifts'!$C:$C,Q$13) -> 4
C16: Shifts to be removed | D16: =COUNTIFS('TEF shifts'!J:J,"Remove") -> 74 | E16: =SUM(M16:Q16)/E$14 -> 0.4047619 | F16: =COUNTIFS('TEF shifts'!$J:$J,"Remove",'TEF shifts'!$C:$C,F$13)/F$14 -> 0.64864865 | G16: =COUNTIFS('TEF shifts'!$J:$J,"Remove",'TEF shifts'!$C:$C,G$13)/G$14 -> 0.12195122 | H16: =COUNTIFS('TEF shifts'!$J:$J,"Remove",'TEF shifts'!$C:$C,H$13)/H$14 -> 0.11111111 | I16: =COUNTIFS('TEF shifts'!$J:$J,"Remove",'TEF shifts'!$C:$C,I$13)/I$14 -> 0.18181818 | J16: =COUNTIFS('TEF shifts'!$J:$J,"Remove",'TEF shifts'!$C:$C,J$13)/J$14 -> 0 | K16: =COUNTIFS('TEF shifts'!$J:$J,"Remove",'TEF shifts'!$C:$C,K$13)/K$14 -> 0 | M16: =COUNTIFS('TEF shifts'!$J:$J,"Remove",'TEF shifts'!$C:$C,M$13) -> 22 | N16: =COUNTIFS('TEF shifts'!$J:$J,"Remove",'TEF shifts'!$C:$C,N$13) -> 2 | O16: =COUNTIFS('TEF shifts'!$J:$J,"Remove",'TEF shifts'!$C:$C,O$13) -> 0 | P16: =COUNTIFS('TEF shifts'!$J:$J,"Remove",'TEF shifts'!$C:$C,P$13) -> 4 | Q16: =COUNTIFS('TEF shifts'!$J:$J,"Remove",'TEF shifts'!$C:$C,Q$13) -> 6
C17: Shifts to be added | D17: =COUNTIFS('TEF shifts'!J:J,"Add shift") -> 86 | E17: =SUM(M17:Q17)/E$14 -> 0.13095238 | F17: =COUNTIFS('TEF shifts'!$J:$J,"Add shift",'TEF shifts'!$C:$C,F$13)/F$14 -> 0.081081081 | G17: =COUNTIFS('TEF shifts'!$J:$J,"Add shift",'TEF shifts'!$C:$C,G$13)/G$14 -> 0.43902439 | H17: =COUNTIFS('TEF shifts'!$J:$J,"Add shift",'TEF shifts'!$C:$C,H$13)/H$14 -> 0.35555556 | I17: =COUNTIFS('TEF shifts'!$J:$J,"Add shift",'TEF shifts'!$C:$C,I$13)/I$14 -> 0.090909091 | J17: =COUNTIFS('TEF shifts'!$J:$J,"Add shift",'TEF shifts'!$C:$C,J$13)/J$14 -> 0.82608696 | K17: =COUNTIFS('TEF shifts'!$J:$J,"Add shift",'TEF shifts'!$C:$C,K$13)/K$14 -> 1 | M17: =COUNTIFS('TEF shifts'!$J:$J,"Add shift",'TEF shifts'!$C:$C,M$13) -> 9 | N17: =COUNTIFS('TEF shifts'!$J:$J,"Add shift",'TEF shifts'!$C:$C,N$13) -> 0 | O17: =COUNTIFS('TEF shifts'!$J:$J,"Add shift",'TEF shifts'!$C:$C,O$13) -> 0 | P17: =COUNTIFS('TEF shifts'!$J:$J,"Add shift",'TEF shifts'!$C:$C,P$13) -> 1 | Q17: =COUNTIFS('TEF shifts'!$J:$J,"Add shift",'TEF shifts'!$C:$C,Q$13) -> 1
B19: Notes: | C19: Shifts to biofuel, gas, hydrogen etc.. have been removed.
C20: In generation of electricity, shifts to all sources have been kept, considering that they would be "altering" the use of the fuel (eg. reducing coal use).
C21: More details on the industrial processes and Afolu were added from climate trace

Sheet TEF shifts
A1: Focus | B1: Sector_1 | C1: Subsector_1 | D1: Subsector_2 | E1: Subsector_3 | F1: Shift | G1: Code_TEF | H1: Name_TEF or new name | I1: Description TEF | J1: Include or remove | K1: Shift | L1: C40 shift category_OLD NAME | M1: Required added granularity | N1: High Impact | O1: Indicator
A2: Mitigation | B2: AFOLU | C2: AFOLU | D2: Source | F2: Activity shift | G2: NA | H2: Reduction in aggregate source emissions | I2: NA | J2: Add shift | K2: =CONCATENATE(C2," > ",D2," > ",E2," > ",F2) -> AFOLU > Source > > Activity shift | L2: AFOLU> Reduction in aggregate source emissions | M2: Note: not in C40 pathways but present in Climate Trace. Less priority
A3: Mitigation | B3: AFOLU | C3: AFOLU | D3: Land | F3: Activity shift | G3: NA | H3: Reduction in Land emissions | I3: NA | J3: Add shift | K3: =CONCATENATE(C3," > ",D3," > ",E3," > ",F3) -> AFOLU > Land > > Activity shift | L3: AFOLU> Reduction in Land emissions | M3: Note: not in C40 pathways but present in Climate Trace. Less priority
A4: Mitigation | B4: AFOLU | C4: AFOLU | D4: Livestock | F4: Activity shift | G4: NA | H4: Reduction in livestock emissions | I4: NA | J4: Add shift | K4: =CONCATENATE(C4," > ",D4," > ",E4," > ",F4) -> AFOLU > Livestock > > Activity shift | L4: AFOLU> Reduction in livestock emissions | M4: Note: not in C40 pathways but present in Climate Trace. Less priority
A5: Mitigation | B5: AFOLU | C5: AFOLU | D5: Land | G5: NA | H5: Synthetic-fertilizer-application - Adopt nitrification/urease inhibitors to cut N‚ÇÇO | I5: NA | J5: Add shift | K5: =L5 -> AFOLU> synthetic-fertilizer-application - Adopt nitrification/urease inhibitors to cut N‚ÇÇO | L5: AFOLU> synthetic-fertilizer-application - Adopt nitrification/urease inhibitors to cut N‚ÇÇO | M5: Note: not in C40 pathways but present in Climate Trace. Less priority
A6: Mitigation | B6: AFOLU | C6: AFOLU | D6: Land | G6: NA | H6: Rice-cultivation - Alternate wetting and drying | I6: NA | J6: Add shift | K6: =L6 -> AFOLU> rice-cultivation - Alternate wetting and drying | L6: AFOLU> rice-cultivation - Alternate wetting and drying | M6: Note: not in C40 pathways but present in Climate Trace. Less priority
A7: Mitigation | B7: AFOLU | C7: AFOLU | D7: Land | G7: NA | H7: Other-chemicals - Alternative fuel use and cleaner production | I7: NA | J7: Add shift | K7: =L7 -> AFOLU> other-chemicals - Alternative fuel use and cleaner production | L7: AFOLU> other-chemicals - Alternative fuel use and cleaner production | M7: Note: not in C40 pathways but present in Climate Trace. Less priority
A8: Mitigation | B8: AFOLU | C8: AFOLU | D8: Land | G8: NA | H8: Rice-cultivation - Balanced fertilizer composition | I8: NA | J8: Add shift | K8: =L8 -> AFOLU> rice-cultivation - Balanced fertilizer composition | L8: AFOLU> rice-cultivation - Balanced fertilizer composition | M8: Note: not in C40 pathways but present in Climate Trace. Less priority
A9: Mitigation | B9: AFOLU | C9: AFOLU | D9: Livestock | G9: NA | H9: Enteric-fermentation-cattle-pasture - Feed additives in cattle diet | I9: NA | J9: Add shift | K9: =L9 -> AFOLU> enteric-fermentation-cattle-pasture - Feed additives in cattle diet | L9: AFOLU> enteric-fermentation-cattle-pasture - Feed additives in cattle diet | M9: Note: not in C40 pathways but present in Climate Trace. Less priority
A10: Mitigation | B10: AFOLU | C10: AFOLU | D10: Livestock | G10: NA | H10: Enteric-fermentation-cattle-operation - Feed additives in cattle diet | I10: NA | J10: Add shift | K10: =L10 -> AFOLU> enteric-fermentation-cattle-operation - Feed additives in cattle diet | L10: AFOLU> enteric-fermentation-cattle-operation - Feed additives in cattle diet | M10: Note: not in C40 pathways but present in Climate Trace. Less priority
A11: Mitigation | B11: AFOLU | C11: AFOLU | D11: Land | G11: NA | H11: Forest-land-clearing - Forest restoration | I11: NA | J11: Add shift | K11: =L11 -> AFOLU> forest-land-clearing - Forest restoration | L11: AFOLU> forest-land-clearing - Forest restoration | M11: Note: not in C40 pathways but present in Climate Trace. Less priority
A12: Mitigation | B12: AFOLU | C12: AFOLU | D12: Land | G12: NA | H12: Manure-applied-to-soils - Inject slurry below surface | I12: NA | J12: Add shift | K12: =L12 -> AFOLU> manure-applied-to-soils - Inject slurry below surface | L12: AFOLU> manure-applied-to-soils - Inject slurry below surface | M12: Note: not in C40 pathways but present in Climate Trace. Less priority
A13: Mitigation | B13: AFOLU | C13: AFOLU | D13: Land | G13: NA | H13: Crop-residues - Residue management with low C:N under 25 | I13: NA | J13: Add shift | K13: =L13 -> AFOLU> crop-residues - Residue management with low C:N under 25 | L13: AFOLU> crop-residues - Residue management with low C:N under 25 | M13: Note: not in C40 pathways but present in Climate Trace. Less priority
A14: Mitigation | B14: AFOLU | C14: AFOLU | D14: Land | G14: NA | H14: Cropland-fires - Residue Removal without burning | I14: NA | J14: Add shift | K14: =L14 -> AFOLU> cropland-fires - Residue Removal without burning | L14: AFOLU> cropland-fires - Residue Removal without burning | M14: Note: not in C40 pathways but present in Climate Trace. Less priority
A15: Mitigation | B15: AFOLU | C15: AFOLU | D15: Livestock | G15: NA | H15: Manure-management-cattle-operation - Shift manure management method | I15: NA | J15: Add shift | K15: =L15 -> AFOLU> manure-management-cattle-operation - Shift manure management method | L15: AFOLU> manure-management-cattle-operation - Shift manure management method | M15: Note: not in C40 pathways but present in Climate Trace. Less priority
A16: Mitigation | B16: Stationary (Buildings) | C16: Residential | D16: Flat | E16: Heating | F16: Fuel shift | G16: T-4A1a-TE-1 | H16: Shift to heat pumps in multi-family buildings | I16: Shift square meter from multi-family buildings heated with gas, oil, direct electric, coal and LPG to multi-family buildings heated with heat pumps in square meter to fulfill the need for comfortable premises | J16: Include | K16: =CONCATENATE(C16," > ",D16," > ",E16," > ",F16) -> Residential > Flat > Heating > Fuel shift | L16: =CONCATENATE(C16," > ",D16," > ",E16," > ",F16) -> Residential > Flat > Heating > Fuel shift | M16: New and existing buildings ; income bands
A17: Mitigation | B17: Stationary (Buildings) | C17: Residential | D17: Flat | E17: Heating | F17: Fuel shift | G17: T-4A1a-TE-2 | H17: Shift to district heating in multi-family buildings | I17: Shift square meter from multi family building heated with gas, oil, direct electric, coal and LPG to multi family building heated with district heating in square meter to fulfill the need of comfortable premises | J17: Include | K17: =CONCATENATE(C17," > ",D17," > ",E17," > ",F17) -> Residential > Flat > Heating > Fuel shift | L17: =CONCATENATE(C17," > ",D17," > ",E17," > ",F17) -> Residential > Flat > Heating > Fuel shift | M17: New and existing buildings ; income bands
A18: Mitigation | B18: Stationary (Buildings) | C18: Residential | D18: Flat | E18: Cooling | F18: Technology shift | G18: T-4A1a-TE-3 | H18: Shift to district cooling in multi-family buildings | I18: Shift square meter from multi family building cooling with AC to multi family building cooling with district cooling in square meter to fulfill the need of comfortable premises | J18: Include | K18: =CONCATENATE(C18," > ",D18," > ",E18," > ",F18) -> Residential > Flat > Cooling > Technology shift | L18: =CONCATENATE(C18," > ",D18," > ",E18," > ",F18) -> Residential > Flat > Cooling > Technology shift | M18: New and existing buildings ; income bands
A19: Mitigation | B19: Stationary (Buildings) | C19: Residential | D19: Flat | E19: Water heating | F19: Fuel shift | G19: T-4A1a-TE-4 | H19: Shift to solar thermal in multi-family buildings | I19: Shift square meter from multi family building heated with gas, oil, direct electric and coal to multi family building heated with solar thermal in square meter to fulfill the need of comfortable premises | J19: Include | K19: =CONCATENATE(C19," > ",D19," > ",E19," > ",F19) -> Residential > Flat > Water heating > Fuel shift | L19: =CONCATENATE(C19," > ",D19," > ",E19," > ",F19) -> Residential > Flat > Water heating > Fuel shift | M19: New and existing buildings ; income bands
A20: Mitigation | B20: Stationary (Buildings) | C20: Residential | D20: Flat | E20: Heating | F20: Fuel shift | G20: T-4A1a-TE-5 | H20: Shift to biofuel heating in multi-family buildings | I20: Shift square meter from multi family building heated with gas oil, direct electric, coal and LPG to multi family building heated with solid biofuels in square meter to fulfill the need of comfortable premises | J20: Remove | L20: Not modelling biofuel transition | M20: NA
A21: Mitigation | B21: Stationary (Buildings) | C21: Residential | D21: Flat | E21: Heating | F21: Activity shift | G21: T-4A1a-TE-6 | H21: Retrofitting multi-family buildings for efficient heating | I21: Reduce the amount of energy required to heat district heating, gas, oil, direct electric, heat pump, solid biofuels, coal, solar thermal and LPG multi family buildings through retrofitting | J21: Include | K21: =CONCATENATE(C21," > ",D21," > ",E21," > ",F21) -> Residential > Flat > Heating > Activity shift | L21: =CONCATENATE(C21," > ",D21," > ",E21," > ",F21) -> Residential > Flat > Heating > Activity shift | M21: New and existing buildings ; income bands
A22: Mitigation | B22: Stationary (Buildings) | C22: Residential | D22: Flat | E22: Cooling | F22: Behaviour shift | G22: T-4A1a-TE-7 | H22: Energy efficient use of ACs in multi-family buildings | I22: Reduce the amount of energy required to cool multi family buildings with AC through efficient use of AC units | J22: Remove | L22: No demand modelling | M22: NA
A23: Mitigation | B23: Stationary (Buildings) | C23: Residential | D23: Flat | E23: Cooling | F23: Technology shift | G23: T-4A1a-TE-8 | H23: Energy efficient AC in multi-family buildings | I23: Reduce the amount of energy required to cool multi family buildings with AC through more efficient AC units | J23: Include | K23: =CONCATENATE(C23," > ",D23," > ",E23," > ",F23) -> Residential > Flat > Cooling > Technology shift | L23: =CONCATENATE(C23," > ",D23," > ",E23," > ",F23) -> Residential > Flat > Cooling > Technology shift | M23: New and existing buildings ; income bands
A24: Mitigation | B24: Stationary (Buildings) | C24: Residential | D24: Flat | E24: Cooling | F24: Activity shift | G24: T-4A1a-TE-9 | H24: Retrofitting multi-family buildings for efficient cooling | I24: Reduce the amount of energy required to cool multi family building with AC and disitrct cooling through retrofitting | J24: Include | K24: =CONCATENATE(C24," > ",D24," > ",E24," > ",F24) -> Residential > Flat > Cooling > Activity shift | L24: =CONCATENATE(C24," > ",D24," > ",E24," > ",F24) -> Residential > Flat > Cooling > Activity shift | M24: New and existing buildings ; income bands
A25: Mitigation | B25: Stationary (Buildings) | C25: Residential | D25: Flat | E25: Water heating | F25: Fuel shift | G25: NA | H25: Change in fuels for water heating in flats | I25: NA | J25: Add shift | K25: =CONCATENATE(C25," > ",D25," > ",E25," > ",F25) -> Residential > Flat > Water heating > Fuel shift | L25: =CONCATENATE(C25," > ",D25," > ",E25," > ",F25) -> Residential > Flat > Water heating > Fuel shift | M25: New and existing buildings ; income bands
A26: Mitigation | B26: Stationary (Buildings) | C26: Residential | D26: Flat | E26: Water heating | F26: Technology shift | G26: NA | H26: Change in efficiency for water heating in flats | I26: NA | J26: Add shift | K26: =CONCATENATE(C26," > ",D26," > ",E26," > ",F26) -> Residential > Flat > Water heating > Technology shift | L26: =CONCATENATE(C26," > ",D26," > ",E26," > ",F26) -> Residential > Flat > Water heating > Technology shift | M26: New and existing buildings ; income bands
A27: Mitigation | B27: Stationary (Buildings) | C27: Residential | D27: Flat | E27: Water heating | F27: Activity shift | G27: NA | H27: Change in amount of water heating in flats | I27: NA | J27: Add shift | K27: =CONCATENATE(C27," > ",D27," > ",E27," > ",F27) -> Residential > Flat > Water heating > Activity shift | L27: =CONCATENATE(C27," > ",D27," > ",E27," > ",F27) -> Residential > Flat > Water heating > Activity shift | M27: New and existing buildings ; income bands
A28: Mitigation | B28: Stationary (Buildings) | C28: Residential | D28: House | E28: Heating | F28: Fuel shift | G28: T-4A1b-TE-1 | H28: Shift to heat pumps in single-family buildings | I28: Shift square meter from single-family buildings heated with gas, oil, direct electric heaters, coal and LPG to single-family buildings heated with heat pumps in square meter to fulfill the need for comfortable premises | J28: Include | K28: =CONCATENATE(C28," > ",D28," > ",E28," > ",F28) -> Residential > House > Heating > Fuel shift | L28: =CONCATENATE(C28," > ",D28," > ",E28," > ",F28) -> Residential > House > Heating > Fuel shift | M28: New and existing buildings ; income bands
A29: Mitigation | B29: Stationary (Buildings) | C29: Residential | D29: House | E29: Heating | F29: Fuel shift | G29: T-4A1b-TE-2 | H29: Shift to district heating in single-family buildings | I29: Shift square meter from single family building heated with gas, oil, direct electric heaters, coal and LPG to single family building heating with district heating in square meter to fulfill the need of comfortable premises | J29: Include | K29: =CONCATENATE(C29," > ",D29," > ",E29," > ",F29) -> Residential > House > Heating > Fuel shift | L29: =CONCATENATE(C29," > ",D29," > ",E29," > ",F29) -> Residential > House > Heating > Fuel shift | M29: New and existing buildings ; income bands
A30: Mitigation | B30: Stationary (Buildings) | C30: Residential | D30: House | E30: Cooling | F30: Technology shift | G30: T-4A1b-TE-3 | H30: Shift to district cooling in single-family buildings | I30: Shift square meter from single family building cooling with AC to single family building cooling with district cooling in square meter to fulfill the need of comfortable premises | J30: Include | K30: =CONCATENATE(C30," > ",D30," > ",E30," > ",F30) -> Residential > House > Cooling > Technology shift | L30: =CONCATENATE(C30," > ",D30," > ",E30," > ",F30) -> Residential > House > Cooling > Technology shift | M30: New and existing buildings ; income bands
A31: Mitigation | B31: Stationary (Buildings) | C31: Residential | D31: House | E31: Water heating | F31: Fuel shift | G31: T-4A1b-TE-4 | H31: Shift to solar thermal in single-family buildings | I31: Shift square meter from single family building heated with gas, oil, direct electric heaters and coal to single family building heated with solar thermal in square meter to fulfill the need of comfortable premises | J31: Include | K31: =CONCATENATE(C31," > ",D31," > ",E31," > ",F31) -> Residential > House > Water heating > Fuel shift | L31: =CONCATENATE(C31," > ",D31," > ",E31," > ",F31) -> Residential > House > Water heating > Fuel shift | M31: New and existing buildings ; income bands
A32: Mitigation | B32: Stationary (Buildings) | C32: Residential | D32: House | E32: Heating | F32: Fuel shift | G32: T-4A1b-TE-5 | H32: Shift to biofuel heating in single-family buildings | I32: Shift square meter from single-family buildings heated with gas, oil, direct electric heaters, coal and LPG to single-family buildings heated with solid biofuels in square meter to fulfill the need for comfortable premises | J32: Remove | L32: Not modelling biofuel transition | M32: NA
A33: Mitigation | B33: Stationary (Buildings) | C33: Residential | D33: House | E33: Heating | F33: Activity shift | G33: T-4A1b-TE-6 | H33: Retrofitting single-family buildings for efficient heating | I33: Reduce the amount of energy required to heat single family building with gas, oil, direct electric heaters, district heating, heat pump, coal, solar thermal, solid biofuels and LPG through retrofitting | J33: Include | K33: =CONCATENATE(C33," > ",D33," > ",E33," > ",F33) -> Residential > House > Heating > Activity shift | L33: =CONCATENATE(C33," > ",D33," > ",E33," > ",F33) -> Residential > House > Heating > Activity shift | M33: New and existing buildings ; income bands
A34: Mitigation | B34: Stationary (Buildings) | C34: Residential | D34: House | E34: Cooling | F34: Behaviour shift | G34: T-4A1b-TE-7 | H34: Energy efficient use of ACs in single-family buildings | I34: Reduce the amount of energy required to cool single family buildings with AC through efficient use of AC units | J34: Remove | L34: No demand modelling | M34: NA
A35: Mitigation | B35: Stationary (Buildings) | C35: Residential | D35: House | E35: Cooling | F35: Technology shift | G35: T-4A1b-TE-8 | H35: Energy efficient AC in single-family buildings | I35: Reduce the amount of energy required to cool single family buildings with AC through more efficient AC units | J35: Include | K35: =CONCATENATE(C35," > ",D35," > ",E35," > ",F35) -> Residential > House > Cooling > Technology shift | L35: =CONCATENATE(C35," > ",D35," > ",E35," > ",F35) -> Residential > House > Cooling > Technology shift | M35: New and existing buildings ; income bands
A36: Mitigation | B36: Stationary (Buildings) | C36: Residential | D36: House | E36: Cooling | F36: Activity shift | G36: T-4A1b-TE-9 | H36: Retrofitting single-family buildings for efficient cooling | I36: Reduce the amount of energy required to cool single family building with AC and disitrct cooling through retrofitting | J36: Include | K36: =CONCATENATE(C36," > ",D36," > ",E36," > ",F36) -> Residential > House > Cooling > Activity shift | L36: =CONCATENATE(C36," > ",D36," > ",E36," > ",F36) -> Residential > House > Cooling > Activity shift | M36: New and existing buildings ; income bands
A37: Mitigation | B37: Stationary (Buildings) | C37: Residential | D37: House | E37: Heating | F37: Fuel shift | G37: T-4A1b-TE-10 | H37: Shift to biogas heating in single-family buildings | I37: Shift square meter from single family residential building heating with gas tosingle family residential building heating with biogas in square meter to fulfill the need of comfortable premises | J37: Remove | L37: Not modelling biomass and biogas | M37: NA
A38: Mitigation | B38: Stationary (Buildings) | C38: Residential | D38: House | E38: Water heating | F38: Fuel shift | G38: NA | H38: Change in fuels for water heating in houses | I38: NA | J38: Add shift | K38: =CONCATENATE(C38," > ",D38," > ",E38," > ",F38) -> Residential > House > Water heating > Fuel shift | L38: =CONCATENATE(C38," > ",D38," > ",E38," > ",F38) -> Residential > House > Water heating > Fuel shift | M38: New and existing buildings ; income bands
A39: Mitigation | B39: Stationary (Buildings) | C39: Residential | D39: House | E39: Water heating | F39: Technology shift | G39: NA | H39: Change in efficiency for water heating in houses | I39: NA | J39: Add shift | K39: =CONCATENATE(C39," > ",D39," > ",E39," > ",F39) -> Residential > House > Water heating > Technology shift | L39: =CONCATENATE(C39," > ",D39," > ",E39," > ",F39) -> Residential > House > Water heating > Technology shift | M39: New and existing buildings ; income bands
A40: Mitigation | B40: Stationary (Buildings) | C40: Residential | D40: House | E40: Water heating | F40: Activity shift | G40: NA | H40: Change in amount of water heating in houses | I40: NA | J40: Add shift | K40: =CONCATENATE(C40," > ",D40," > ",E40," > ",F40) -> Residential > House > Water heating > Activity shift | L40: =CONCATENATE(C40," > ",D40," > ",E40," > ",F40) -> Residential > House > Water heating > Activity shift | M40: New and existing buildings ; income bands
...

Sheet Pathways and Bank actions
A1: ID | B1: Sector | C1: action_name | D1: Type | E1: Type 2 | F1: description | G1: NEW_action_id | H1: subsector_names | I1: Pathways equivalent | J1: Climate trace equivalent
A2: c40_0023 | B2: Transport | C2: Adopt zero-emission bus fleets for public transport | D2: Efficiency | E2: infrastructure | F2: "Adopt zero-emission bus fleets for public transport" mitigation focuses on transitioning public transport fleets to zero-emission buses. According to the HIA, this means that the city or transit operator procures only zero-emission buses (from 2020 onwards). This strategy eliminates tailpipe emissions from traditional buses, improves air quality, and supports a sustainable and resilient urban transport system. Eco-driving training and maintenance programs can be implemented in parallel to maximize efficiency gains and emission reductions during the fleet transition. | G2: rev_c40_0023 | H2: on-road | I2: Passenger vehicle - fuel switch/efficiency | J2: Transition to EVs
A3: c40_0025 | B3: Transport | C3: Promote deployment of zero-emission freight fleets (trucks) | D3: Efficiency | E3: Public | F3: "Promote deployment of zero-emission freight fleets (trucks)" mitigation involves adopting cleaner fuels and technologies to reduce the environmental impact of freight transportation. This initiative aims to decrease air pollution, promote sustainability, and improve the overall efficiency of urban logistics. Eco-driving training and maintenance programs can be implemented in parallel to maximize efficiency gains and emission reductions during the fleet transition. | G3: rev_c40_0025 | H3: on-road
A4: c40_0029 | B4: Transport | C4: Electrify municipal vehicle fleets | D4: Efficiency | E4: infrastructure | F4: The city transitions its municipal vehicle fleets to electric vehicles, beginning with high-impact segments such as buses and garbage trucks. According to HIA guidance, this aligns with the broader objective of implementing key measures to promote transport electrification. Cities can adopt phased strategies, starting with their own fleets, then expanding through incentives for private sector fleets and gradually scaling as charging infrastructure develops. Emphasis should be placed on equity to ensure low-income areas also benefit from cleaner, quieter transport. Eco-driving training and maintenance programs can be implemented in parallel to maximize efficiency gains and emission reductions during the fleet transition. | G4: rev_c40_0029 | H4: on-road
A5: icare_0117 | B5: Transport | C5: Improve public transport systems to promote modal shift | D5: Activity | E5: Public | F5: Implements measures to enhance the coverage, frequency, capacity, speed, reliability, accessibility, resilience, safety, affordability, comfort, and convenience of public transport systems (e.g., buses, BRT, informal transport, intra-city rail). Specific actions include expanding routes, improving service frequency and reliability, integrating ticketing systems, and ensuring universal accessibility. These improvements encourage passengers to shift from private motorized transport to public transport, reducing emissions and supporting more sustainable mobility. | H5: on-road | I5: Mode shift - transit | J5: NA
A6: icare_0121 | B6: Transport | C6: Incentive to create bike-sharing programs in urban areas, with a focus on electric bikes. | D6: Activity | E6: Public | F6: This action encourages the establishment of bike-sharing systems in cities, specifically promoting the use of electric bicycles. These systems allow residents to rent electric bikes for short trips, reducing the dependence on cars for urban transportation. By integrating electric bikes, cities can further reduce greenhouse gas emissions, alleviate traffic congestion, and promote a healthier and more sustainable mode of transportation for both urban and rural areas. This initiative also supports mobility equality, as it makes bikes more accessible to a wider range of people. | H6: on-road | I6: Mode shift - walk/bike | J6: NA
A7: icare_0139 | B7: Transport | C7: Implement congestion pricing and restrictions on high-polluting vehicles | D7: Activity, Efficiency | E7: Public | F7: The city introduces congestion pricing and related restrictions (such as tolls, charges, or bans) on high-polluting vehicles that cover significant parts of the city. To ensure equity and social acceptance, design measures may include exemptions or discounts for low-income drivers, reinvestment of revenues into public transport and active mobility, and strong communication campaigns. While congestion pricing can deliver major emission reductions, it requires substantial governance capacity and is best suited for larger metropolitan areas. | H7: on-road | I7: Vehicle - fuel switch/efficiency | J7: NA
A8: ipcc_0001 | B8: Transport | C8: Promote compact urban form and transit-oriented development | D8: Activity | E8: Public | F8: Encourages compact and mixed-use urban development to reduce travel distances, car dependency, and related GHG emissions. Measures include transit-oriented development (TOD), zoning reforms, densification around transport corridors, and integration of land use and mobility planning. Particularly suited for larger cities with the capacity to update master plans and invest in transit infrastructure. | H8: on-road | I8: Transit oriented development - reduction in activity | J8: NA
A9: ipcc_0105 | B9: Transport | C9: Promote active mobility through road space reallocation | D9: Activity | E9: Public | F9: Promotes walking and cycling by reallocating road space from cars to active and sustainable modes on a permanent basis. Measures include developing pedestrian pathways, protected cycling infrastructure, green corridors, and universal accessibility improvements. By prioritizing active mobility, cities enhance public health, equity, and resilience while reducing emissions from private vehicles. | G9: rev_ipcc_0001_2 | I9: Mode shift - walk/bike | J9: NA
A10: c40_0034 | B10: Waste | C10: Enact and enforce material bans in order to restrict single use and non-recyclable materials | D10: Activity | E10: Public | F10: Impose restrictions on single-use or non-recyclable materials (e.g., single-use plastics, Styrofoam bans) to reduce environmental impact and promote the use of sustainable alternatives, contributing to waste reduction and overall environmental conservation. | G10: rev_c40_0034 | H10: disposal_of_solid_waste_generated_in_the_city | I10: NA | J10: Diversion and Management
A11: c40_0035 | B11: Waste | C11: Optmize waste management systems | D11: Activity | E11: infrastructure | F11: Improve the efficiency of waste management systems, throught the development ou actualization of municipal planning or strategies and implementation of alterntives to expand the service coverage to more areas of the municipality, increase energy efficiency, segregated collection, adequate treatment, promote sustainable waste disposal practices, improve the monitoring of regular disposal and waste deposits, reduce resource consumption and minimize environmental impact. | G11: rev_c40_0035 | H11: all | I11: NA | J11: Diversion and Management
A12: c40_0036 | B12: Waste | C12: Upgrade Landfills to Engineered Sanitary Landfills with Gas Capture. | D12: Efficiency | E12: infrastructure | F12: "Upgrade Landfills to Engineered Sanitary Landfills with Gas Capture." strategies focus on responsible and sustainable landfill practices to minimize environmental degradation. By adopting effective management techniques, cities aim to reduce the ecological footprint associated with landfill sites and encourage waste reduction. | H12: all | I12: NA | J12: Diversion and daily/intermediate cover (sanitary landfill)
A13: c40_0037 | B13: Waste | C13: Implement residential and business segregated collection of recyclables, organic, and residual waste | D13: Activity | E13: Public | F13: Establish citywide three-bin waste separation systems-recyclables, organic waste, and residual waste, for households and businesses. Municipal governments play a central role by organizing segregated collection, running awareness campaigns, and providing training and engagement programs to ensure residents and businesses adopt correct waste sorting practices. Clear communication, adequate infrastructure, and continuous monitoring make this action scalable and practical for cities of all sizes, improving recycling rates and reducing landfill dependency. Cities should ensure universal coverage, address underserved areas, and monitor illegal dumping to achieve full implementation of segregated collection. Ensure that both dry and organic materials are collected separately, and strengthen recycling cooperatives as part of the system’s implementation. | G13: rev_c40_0037 | H13: all | I13: NA | J13: NA
A14: c40_0040 | B14: Waste | C14: Implement Volume-Based Collection policy | D14: Activity | E14: Public | F14: Implement volume based collection fees that reward generators that geneerate less waste and impose higher fees on larger generators. This policy should incentivize waste reduction in the cities. | G14: rev_c40_0040 | H14: all | I14: NA | J14: NA
A15: icare_0053 | B15: Waste | C15: Support cooperatives of voluntary waste collectors to aggregate into small enterprises and expand into organics management | D15: Activity | E15: Public | F15: Measures to aggregate voluntary waste collectors into small enterprises or associtations, improve working conditions and income in the processes of sorting recyclable and organic waste to contribute for GHG emissions reduction and the increase climate risk resilience. It includes mapping individual and groups of voluntary waste collectors, provide training for collectors in waste management and treatement technologies, economics, business management, and conceptual planning for the operation and administration of the Sorting Unit. | G15: rev_icare_0053 | H15: disposal_of_solid_waste_generated_in_the_city | I15: NA | J15: NA
A16: icare_0064 | B16: Waste | C16: Develop an organic waste management strategy | D16: Activity | E16: infrastructure | F16: Development of an organic waste management strategy with near, mid and long term interventions, integrating aquisition and implementation of organic waste treatment technologies and resources to build the adequate infrastructure to treat the collected waste, such as composting, biodigestion and other technologies, in order to reduce the amount sent to landfills and to achieve maximum organics waste diversion | G16: rev_icare_0064 | H16: biological_treatment_of_waste_generated_in_the_city | I16: NA | J16: NA
A17: icare_0110 | B17: Waste | C17: Regulate Construction and Demolition Waste Management to improve deconstruction, segregation at source, reutilization and recycling | D17: Activity | E17: Public | F17: Establish comprehensive guidelines for the sustainable management of construction and demolition waste (CDW) to promote efficiency, circularity, and environmental responsibility across the construction sector. The action aims to reduce waste generation at the source, encourage selective deconstruction instead of conventional demolition, and foster material segregation, reuse, and recycling. These guidelines should define technical standards, responsibilities, and incentives for all stakeholders involved — including contractors, developers, and waste operators — to ensure that valuable materials such as concrete, metals, wood, and aggregates are recovered and reintegrated into new construction cycles. The framework should also establish procedures for safe handling, transportation, and disposal of non-recyclable materials, ensuring compliance with environmental regulations and minimizing landfill use. | G17: rev_icare_0110 | H17: disposal_of_solid_waste_generated_in_the_city | I17: NA | J17: NA
A18: icare_0111 | B18: Waste | C18: Strengthen Extended Producer Responsibility (EPR) Systems | D18: Activity | E18: Public | F18: Enhance processes for returning products to the production cycle, encouraging collection, reuse, and recycling. | H18: disposal_of_solid_waste_generated_in_the_city | I18: NA | J18: NA
A19: icare_0122 | B19: Waste | C19: Establish eco-parks. | D19: Activity | E19: infrastructure | F19: An eco-park is a facility for the mechanical and biological treatment of urban solid waste, integrating different technologies for the segregation and treatment of various fractions within the waste. This treatment aims to maximize the recovery of dry and organic waste and reduce the volume of waste to be sent for final disposal in landfills, using technologies such as energy generation, composting, recycling recovery, proper disposal of residual waste, and other existing treatment methods available in the market. By integrating these processes , eco-parks operate as multi-technology hubs for waste management, fostering synergies between waste reduction, energy recovery, and environmental protection for the cities. They also contribute to green job creation, climate change mitigation, and urban sustainability. | G19: rev_icare_0122 | H19: land | I19: Recycling | J19: Diversion and shut down
A20: c40_0010 | B20: Stationary Energy | C20: Introduce energy-efficiency standards for new residential buildings | D20: Activity | E20: Public | F20: The city adopts new energy-efficiency standards for residential construction, ensuring all new buildings incorporate design and performance requirements such as improved thermal insulation, natural ventilation, shading devices, efficient lighting (LED), and solar-ready wiring for PV integration. Standards may also establish region-dependent requirements for cooling demand reduction (e.g., reflective roofs, cross-ventilation) and may also include whole life carbon requirements and promote the use of sustainable materials. Smaller cities can integrate these requirements into basic building codes, while larger cities can introduce advanced certifications or municipal green building standards. | G20: rev_c40_0010 | H20: residential_buildings | I20: Envelope (insulation, window, roof) | J20: NA
A21: c40_0012 | B21: Stationary Energy | C21: Introduce energy-efficiency standards for new institutional buildings | D21: Activity | E21: infrastructure | F21: The city introduces energy-efficient and resource-efficient standards for schools, hospitals, and other public buildings, setting an example for sustainable construction. Standards should mandate efficient HVAC systems with proper zoning, daylighting strategies to reduce artificial lighting, occupancy sensors, reflective roofs, and integration of photovoltaic (PV) systems where feasibleand. They can also include whole life carbon requirements and promote the use of sustainable materials. Requirements may vary depending on regional climate conditions to address specific cooling or thermal comfort needs. | G21: rev_c40_0012 | H21: institutional_buildings | I21: Envelope (insulation, window, roof) | J21: NA
A22: c40_0013 | B22: Stationary Energy | C22: Support Implementation of Industrial Building Efficiency Standards. | D22: Activity, Efficiency | E22: Public | F22: "Support Implementation of Industrial Building Efficiency Standards" set guidelines for environmentally responsible construction, ensuring that new structures adhere to energy-efficient practices, thereby reducing carbon emissions and promoting sustainable urban development. Standards may also include whole life carbon requirements and promote the use of sustainable materials. | H22: manufacturing_industries_and_construction | I22: Equipement - efficiency | J22: NA
A23: c40_0015 | B23: Stationary Energy | C23: Retrofit residential buildings for energy efficiency | D23: Activity | E23: Public | F23: The city supports retrofitting existing residential buildings to improve energy efficiency and reduce emissions. Key interventions include replacing inefficient refrigerators, air conditioners, and lighting with high-efficiency models (e.g., PROCEL Seal appliances), sealing windows and doors to reduce air leakage, and improving indoor comfort through natural ventilation and shading. Municipalities can facilitate access to financing programs, bulk procurement, and technical assistance for households to adopt upgrades. Retrofits should prioritize passive cooling strategies (shading, ventilation) before installing high-efficiency cooling technologies using low-GWP refrigerants. | G23: rev_c40_0015 | H23: residential_buildings | I23: Envelope (insulation, window, roof) | J23: NA
A24: c40_0016 | B24: Stationary Energy | C24: Retrofit commercial and institutional other non-residential buildings for energy efficiency | D24: Activity | E24: Public | F24: The city promotes energy retrofits in commercial and institutional buildings such as offices, shopping centers, universities, and hotels. Measures include upgrading HVAC systems with variable refrigerant flow (VRF) units, replacing fluorescent and halogen lighting with LEDs, implementing building automation and energy management systems, and improving the thermal envelope (insulation, reflective coatings, shading). Region-specific adaptations may also be required to address cooling and comfort needs. Retrofits often deliver short payback periods through lower operating costs and enhanced occupant comfort. Retrofits should prioritize passive cooling strategies (shading, ventilation) before installing high-efficiency cooling technologies using low-GWP refrigerants. | G24: rev_c40_0016 | H24: commercial_and_institutional_buildings_and_facilities | I24: Envelope (insulation, window, roof) | J24: NA
A25: c40_0017 | B25: Stationary Energy | C25: Retrofit municipal buildings for energy efficiency | D25: Activity | E25: infrastructure | F25: The city leads by example through energy retrofits in municipal buildings, including schools, health centers, and administrative offices. Interventions include replacing outdated air conditioners with high-efficiency models, upgrading lighting to LEDs with smart controls, improving building envelopes with reflective roofs and shading, and installing energy management systems for real-time monitoring. Adaptations should reflect regional climate conditions to ensure cost-effective energy savings. By prioritizing its own facilities, the city demonstrates leadership, reduces operating expenses, and showcases practical solutions that can be replicated by the private sector. Retrofits should prioritize passive cooling strategies (shading, ventilation) before installing high-efficiency cooling technologies using low-GWP refrigerants. | G25: rev_c40_0017 | H25: commercial_and_institutional_buildings_and_facilities | I25: Envelope (insulation, window, roof) | J25: NA
A26: c40_0018 | B26: Stationary Energy | C26: Optimize energy efficiency and sustainability standards for existing industrial infrastructure | D26: Activity | E26: Public | F26: The city will promote the optimization of energy and environmental performance in existing industrial infrastructure, aiming to maximize efficiency, reduce emissions, and lower operational costs. This action focuses on upgrading equipment, improving process efficiency, and retrofitting industrial facilities to meet higher sustainability standards. Municipal roles may include providing incentives for energy audits and retrofits, facilitating partnerships with industry associations and utilities, and adopting regulations or voluntary standards aligned with national efficiency programs. These measures enhance industrial competitiveness, reduce resource intensity, and contribute to the city’s broader decarbonization and circular economy objectives. | G26: rev_c40_0018 | H26: manufacturing_industries_and_construction | I26: Industrial - efficiency | J26: NA
A27: c40_0071 | B27: Stationary Energy | C27: Promote the phase out the reliance on fossil fuels for cooking (in favour of high-efficiency electric cookstoves such as induction stoves). | D27: Activity, Efficiency | E27: Public | F27: Promote the phase out the reliance on fossil fuels for cooking encourage environmentally friendly cooking practices, including the use of energy-efficient appliances and sustainable cooking methods. This strategy promotes resource conservation and contributes to overall sustainability in food preparation. | G27: rev_c40_0071 | I27: Cooking - fuel switch | J27: Technology retrofit (cooking)
A28: icare_0002 | B28: Stationary Energy | C28: Promote and expand the use of the Brazilian Energy Labeling Program for Buildings | D28: Activity | E28: Public | F28: The city will encourage the adoption and enforcement of the Brazilian Energy Labeling Program for Buildings to improve energy efficiency and reduce emissions from the building sector. The program evaluates and certifies buildings based on their energy performance, covering aspects such as thermal efficiency, lighting, and HVAC systems. Actions may include incentivizing developers and property owners to seek certification, integrating energy performance criteria into municipal building codes, and raising public awareness of the benefits of energy-efficient construction and renovation. | G28: rev_icare_0002 | H28: residential_buildings | I28: Equipement - efficiency | J28: NA
A29: icare_0006 | B29: Stationary Energy | C29: Develop integrated renewable energy planning and solar–battery microgrids for rural and peri-urban areas | D29: Activity | E29: Public | F29: The city will promote integrated regional energy planning to ensure that electricity expansion in rural and peri-urban areas is cost-effective, low-emission, and equitable. This approach combines renewable energy generation (e.g., solar PV and wind) with battery storage and microgrid systems to extend reliable access to electricity where traditional grid expansion is unviable or inefficient. Municipalities can partner with energy utilities, rural cooperatives, and neighboring jurisdictions to identify optimal locations for solar–battery microgrids or distributed renewable infrastructure, especially in areas adjoining urban centers where land availability supports clean energy generation for both city and rural users. Financing mechanisms may include public–private artnerships (PPPs), leasing models, concessional loans, and power purchase agreements (PPAs). | G29: rev_icare_0006 | H29: energy_generation_supplied_to_the_grid | I29: Distributed renewables | J29: Replace activity with solar generation
A30: icare_0008 | B30: Stationary Energy | C30: Enable smart grid integration and distributed energy storage through municipal collaboration and demonstration projects | D30: Activity | E30: Public | F30: The city will collaborate with energy utilities, regulators, and technology providers to support the deployment of smart grid infrastructure and distributed energy storage systems that enhance flexibility, reliability, and renewable energy integration. While large-scale grid modernization is typically led by national or regional authorities | G30: rev_icare_0008 | H30: energy_industries | I30: Distributed renewables | J30: Replace activity with solar generation
A31: icare_0009 | B31: Stationary Energy | C31: Deploy cogeneration systems in industries | E31: Public | F31: Utilize combined heat and power systems to maximize energy efficiency in industrial processes. | H31: manufacturing_industries_and_construction | I31: Industrial - fuel switch | J31: Alternative fuel usage
A32: icare_0010 | B32: Stationary Energy | C32: Promote Net-Zero and Green Building Certifications | E32: Public | F32: This action focuses on promoting sustainable buildings by supporting net-zero energy goals and encouraging green building certifications such as LEED. It aims to incentivize the construction and renovation of buildings that produce as much energy as they consume, reducing their environmental impact. This initiative also fosters the adoption of sustainable practices and technologies, ensuring long-term energy efficiency and environmental responsibility across residential, commercial, and public infrastructure. | H32: residential_buildings | I32: Envelope (insulation, window, roof) | J32: NA
A33: icare_0012 | B33: Stationary Energy | C33: Expand solar energy generation on municipal facilities and public assets | E33: infrastructure | F33: The city will install and scale up solar photovoltaic (PV) systems on municipal buildings and public assets, including schools, health centers, administrative offices, bus terminals, water treatment plants, and decommissioned landfills. The objective is to increase the share of renewable electricity in municipal operations, lower energy costs, and reduce greenhouse gas emissions. Facilitating pilot and demonstration projects in municipal buildings, neighborhoods, or industrial zones to showcase the benefits of smart meters, automated controls, and local storage systems; Supporting demand-side flexibility programs, such as time-of-use tariffs and smart appliance initiatives; Incorporating grid-readiness and distributed generation planning into local development and zoning strategies; and Engaging in integrated resource planning with utilities to ensure that urban and peri-urban energy needs are aligned with regional grid upgrades. | G33: rev_icare_0012 | H33: energy_generation_supplied_to_the_grid | I33: Distributed renewables | J33: Replace activity with solar generation
A34: icare_0015 | B34: Stationary Energy | C34: Promote Mini and Micro-Hydropower and Biomass Energy | E34: Public | F34: This action focuses on promoting renewable energy generation by developing mini and micro-hydropower plants and encouraging biomass energy production in agricultural regions. By harnessing the potential of local water resources and organic waste, this initiative aims to diversify the energy mix, improve energy security, and support sustainable agricultural practices, reducing dependence on fossil fuels while promoting environmentally friendly energy solutions. | H34: energy_generation_supplied_to_the_grid | I34: Grid decarbonisation | J34: Replace activity with solar generation
A35: icare_0016 | B35: Stationary Energy | C35: Promote solar thermal and heat pump systems for water heating in residential, commercial, and public buildings | E35: Public | F35: The city will encourage the adoption of renewable and efficient water heating systems, including solar thermal collectors and heat pumps, across residential, commercial, and public facilities. These systems significantly reduce energy consumption and emissions associated with conventional electric or gas water heating. Municipal actions may include: Installing systems in public buildings (schools, hospitals, sports centers) to demonstrate leadership and reduce operational costs; Providing incentives or financing programs for residential and commercial installations; and Updating building codes or efficiency standards to integrate renewable heating technologies in new and retrofitted constructions. | G35: rev_icare_0016 | H35: residential_buildings | I35: Water heating: efficiency / fuel switch | J35: Technology retrofit (water-heating)
A36: icare_0023 | B36: Stationary Energy | C36: Upgrade and maintain electrical substations | E36: Public | F36: Enhance the reliability and efficiency of the electrical grid by modernizing substation equipment and implementing regular maintenance programs. | H36: energy_industries | I36: NA | J36: NA
A37: icare_0024 | B37: Stationary Energy | C37: Integrate renewables into municipal water systems | E37: infrastructure | F37: Implement renewable energy sources, such as solar or wind power, to drive water treatment, pumping, and distribution systems, reducing energy costs and emissions. | H37: energy_generation_supplied_to_the_grid | I37: Distributed renewables | J37: NA
A38: icare_0025 | B38: Stationary Energy | C38: Promote energy-efficient and climate-resilient housing for low-income and informal settlements | E38: Public | F38: The city will develop and support housing programs that integrate energy-efficient and climate-resilient design principles, reducing energy costs and improving comfort for low-income households and residents of informal settlements. Measures may include the use of thermal insulation materials, reflective roofing, natural ventilation, and efficient lighting and appliances (such as LEDs and solar water heaters). Municipal actions can involve incentivizing retrofits, integrating efficiency criteria into social housing programs, and offering technical assistance or subsidies for small-scale upgrades. This action can be combined with broader improvement projects that address sanitation, water access, and structural safety, fostering integrated and inclusive neighborhood upgrading. These interventions enhance quality of life, reduce energy poverty, and contribute to urban climate mitigation and adaptation goals. | G38: rev_icare_0025 | H38: residential_buildings | I38: Envelope (insulation, window, roof) | J38: NA
A39: icare_0026 | B39: Stationary Energy | C39: Implement time-of-use electricity tariffs to enhance demand-side flexibility and efficiency | E39: Public | F39: The city will work with energy regulators and utilities to introduce time-of-use (TOU) electricity tariffs that incentivize consumers to shift energy use toward off-peak hours. By encouraging demand-side flexibility, this measure helps to balance grid demand, ensure grid stability, and lower energy costs for consumers, particularly when combined with energy-efficient appliances and smart metering technologies. Municipal roles may include advocating for regulatory approval, piloting TOU programs in public facilities, and raising awareness among residential, commercial, and industrial users. This action supports the city’s broader energy efficiency and resilience objectives, helping to integrate renewable energy more effectively and reduce peak load pressures. | G39: rev_icare_0026 | H39: energy_industries | I39: NA | J39: NA
A40: icare_0027 | B40: Stationary Energy | C40: Create financing programs for local renewable energy projects | E40: Public | F40: Establish funding mechanisms, such as grants and low-interest loans, to support the development of small-scale renewable energy initiatives in communities. These programs can also support community renewable energy farms and cooperatives, enabling shared access to clean power and strengthening local ownership models. | G40: rev_icare_0027 | H40: energy_industries | I40: NA | J40: NA
...
